Workbook

Sheet ХК
A1: Учтепа сити маркази лойиҳасини амалга ошириш бўйича концептуал бизнес
A2: РЕЖА
A4: Харажатлар:
A6: I. Компенсация | C6: Сони | D6: Ер майдони (м2) | F6: Сумма ($)
A7: ◦ | B7: Якка тартибдаги уйлар | C7: 151 | D7: =Турар!H165 -> 117891 | F7: 77000000
A8: ◦ | B8: Нотурар объектлар | C8: 16 | D8: =Нотурар!H27-ХК!D9 -> 23771 | F8: 23900000
A9: ◦ | B9: Давлат объектлари | C9: 2 | D9: =Нотурар!H10+Нотурар!H11 -> 56901 | F9: 15000000
A10: ЖАМИ: | F10: =SUM(F7:F9) -> 115900000
B12: *Якка тартибдаги уйлар 1 сўтих нархи = $55 минг
B13: *Нотурар объектлар сўтих нархи = $100 минг
B14: *Давлат объектлари ВМ 414га асосан Тез ёрдам ва Сувсоз дирекция томонидан кўчирилади
A16: II. Ички коммуникация | C16: Параметрлари | D16: Миқдори | E16: Нархи($) | F16: Сумма ($)
A17: ◦ | B17: Автомбиль йўллари | C17: Кенглиги -12 метр | D17: 3,6 км | E17: 1000000 | F17: 3600000
A18: ◦ | B18: Электр тақсимлаш пункти ва электр.таъминоти | C18: 48 ячейкага - 24 корхона | D18: 2та/ 3,6 км | E18: 450000 | F18: 900000
A19: ◦ | B19: Электр кабел тармоқлари | C19: 240 АпВПУ - 10 кВ | D19: 3,6 км | E19: 205000 | F19: 738000
A20: ◦ | B20: Сув оқава тармоқлари | C20: 300 диаметрлик | D20: 3,6 км | E20: 60000 | F20: 216000
A21: ◦ | B21: Ичимлик суви тармоқлари | C21: 301 диаметрлик | D21: 3,6 км | E21: 75000 | F21: 270000
A22: ◦ | B22: Бўзсув канали бўйини ободонлаштириш | C22: Сайилгоҳ | D22: 40 000 м2 | E22: 100 | F22: 4000000
A23: ЖАМИ: | F23: =SUM(F17:F22) -> 9724000
A25: III. Бошқа харажатлар
A26: ◦ | B26: Ҳудудни қурилиш чиқиндиларидан тозалаш | F26: 1000000
A27: ◦ | B27: Дирекцияни моддий база билан таъминлаш ва сақлаш харажатлари (5 йил) | F27: 6000000
A28: ◦ | B28: Кўзда тутилмаган (кутилмаган) харажатлар (1,5%) | F28: 1800000
A29: ЖАМИ: | F29: =SUM(F26:F28) -> 8800000
A31: Лойиҳани амалга ошириш учун жами сарф-харажатлар | E31: =F10+F23+F29 -> 134424000
A35: Зарарсизлик нуқтаси ҳисоб-китоби
A37: → | B37: Жами сарф-харажатлар | D37: =E31 -> 134424000
A38: → | B38: Сотувга чиқариладиган ер майдони (м2) | D38: 179000
A39: → | B39: 1 м2 зарарсизлик нуқтаси | D39: =D37/D38 -> 750.97207
B41: Лойиҳа тўлиқ якунига етказиш учун 1 сўтиҳ ер майдонини електрон савдога чиқариладиган энг паст баҳоланган нархи ~ $75минг.

Sheet Лот кесимида
A1: Лот рақами | B1: Лот майдони (кв.м.) | C1: Компенсация харажатлари | E1: Бошқа харажатлар тақсимоти (ички коомуникация, автомобиль йўллари ва бошқалар | F1: ЖАМИ харажатлар | G1: 1 м2 зарарсизлик нуқтаси
C2: Турар | D2: Нотурар
A3: 1 | B3: 6900 | C3: =Турар!Q6 -> 8024700 | E3: =(ХК!$F$23+ХК!$F$29)/$B$17*B3 -> 714053.63 | F3: =C3+D3+E3 -> 8738753.6 | G3: =F3/B3 -> 1266.486
A4: 2 | B4: 17300 | C4: =Турар!Q20 -> 8070350 | E4: =(ХК!$F$23+ХК!$F$29)/$B$17*B4 -> 1790308.4 | F4: =C4+D4+E4 -> 9860658.4 | G4: =F4/B4 -> 569.98025
A5: 3 | B5: 6500 | C5: =Турар!Q23 -> 697800 | D5: =Нотурар!L4 -> 706000 | E5: =(ХК!$F$23+ХК!$F$29)/$B$17*B5 -> 672659.22 | F5: =C5+D5+E5 -> 2076459.2 | G5: =F5/B5 -> 319.45526 | J5: 20618000
A6: 4 | B6: 5900 | D6: =Нотурар!L6 -> 1045000 | E6: =(ХК!$F$23+ХК!$F$29)/$B$17*B6 -> 610567.6 | F6: =C6+D6+E6 -> 1655567.6 | G6: =F6/B6 -> 280.60468
A7: 5 | B7: 14600 | D7: =$J$5/($B$7+$B$8+$B$9)*B7 -> 10238871 | E7: =(ХК!$F$23+ХК!$F$29)/$B$17*B7 -> 1510896.1 | F7: =C7+D7+E7 -> 11749767 | G7: =F7/B7 -> 804.77855
A8: 6 | B8: 6300 | D8: =$J$5/($B$7+$B$8+$B$9)*B8 -> 4418142.9 | E8: =(ХК!$F$23+ХК!$F$29)/$B$17*B8 -> 651962.01 | F8: =C8+D8+E8 -> 5070104.9 | G8: =F8/B8 -> 804.77855
A9: 7 | B9: 8500 | D9: =$J$5/($B$7+$B$8+$B$9)*B9 -> 5960986.4 | E9: =(ХК!$F$23+ХК!$F$29)/$B$17*B9 -> 879631.28 | F9: =C9+D9+E9 -> 6840617.7 | G9: =F9/B9 -> 804.77855
A10: 8 | B10: 8400 | C10: =Турар!Q29 -> 1629100 | D10: =Нотурар!L15 -> 1098000 | E10: =(ХК!$F$23+ХК!$F$29)/$B$17*B10 -> 869282.68 | F10: =C10+D10+E10 -> 3596382.7 | G10: =F10/B10 -> 428.1408
A11: 9 | B11: 22200 | C11: =Турар!Q62 -> 13881100 | D11: =Нотурар!L17 -> 2328000 | E11: =(ХК!$F$23+ХК!$F$29)/$B$17*B11 -> 2297389.9 | F11: =C11+D11+E11 -> 18506490 | G11: =F11/B11 -> 833.62567
A12: 10 | B12: 20400 | C12: =Турар!Q100 -> 16654403 | D12: ='[1]Турар Лотлар '!S119 -> 63740 | E12: =(ХК!$F$23+ХК!$F$29)/$B$17*B12 -> 2111115.1 | F12: =C12+D12+E12 -> 18829258 | G12: =F12/B12 -> 923.00285
A13: 11 | B13: 2400 | C13: МТМ ҳудуди | E13: =(ХК!$F$23+ХК!$F$29)/$B$17*B13 -> 248366.48 | F13: =E13 -> 248366.48 | G13: =F13/B13 -> 103.48603
A14: 12 | B14: 39300 | C14: =Турар!Q141 -> 18398000 | D14: =Нотурар!L24 -> 11893000 | E14: =(ХК!$F$23+ХК!$F$29)/$B$17*B14 -> 4067001.1 | F14: =C14+D14+E14 -> 34358001 | G14: =F14/B14 -> 874.24939
A15: 13 | B15: 5100 | C15: =Турар!Q149 -> 2821200 | E15: =(ХК!$F$23+ХК!$F$29)/$B$17*B15 -> 527778.77 | F15: =C15+D15+E15 -> 3348978.8 | G15: =F15/B15 -> 656.6625
A16: 14 | B16: 15200 | C16: =Турар!Q161 -> 6182800 | D16: =Нотурар!L26 -> 1150000 | E16: =(ХК!$F$23+ХК!$F$29)/$B$17*B16 -> 1572987.7 | F16: =C16+D16+E16 -> 8905787.7 | G16: =F16/B16 -> 585.90709
A17: ЖАМИ | B17: =SUM(B3:B16) -> 179000 | C17: =SUM(C3:C16) -> 76359453 | D17: =SUM(D3:D16) -> 38901740 | E17: =SUM(E3:E16) -> 18524000 | F17: =SUM(F3:F16) -> 133785193
A20: Умумий лотлар маълумоти
A21: Лот рақами | C21: Компенсация суммаси (дастлабки ҳ-к бўйича)
A22: 1 | C22: =C3+#REF! -> #REF!
A23: 2 | C23: =C4+#REF! -> #REF!
A24: 3 | C24: =C5+#REF! -> #REF!
A25: 4 | C25: =C6+#REF! -> #REF!
A26: 5 | C26: =C7+#REF! -> #REF!
A27: 6 | C27: =C8+#REF! -> #REF!
A28: 7 | C28: =C9+#REF! -> #REF!
A29: 8 | C29: =C10+#REF! -> #REF!
A30: 9 | C30: =C11+#REF! -> #REF!
A31: 10 | C31: =C12+#REF! -> #REF!
A32: 11 | C32: =#REF!+#REF! -> #REF!
A33: 12 | C33: =C14+#REF! -> #REF!
A34: 13 | C34: =C15+#REF! -> #REF!
A35: 14 | C35: =C16+#REF! -> #REF!
C36: =SUM(C22:C35) -> #REF!

Sheet Турар
A1: № | B1: К/р | C1: ЛОТ | D1: Мулкдор | E1: Кадастр рақами | F1: Кўча | G1: Уй рақами | H1: Хужжат бўйича Ер майдони, кв.м. | I1: Умумий ер майдони кв.м. | J1: Ўзбошимча ер майдони кв.м. | K1: Қурилиш оости майдони кв.м. | L1: Яшаш майдони кв.м. | M1: Хуқуқ тури | N1: Ер нархи кв.м. $ 500-800 | O1: Бино нархи $ 300
A2: 1 | B2: 1 | C2: 1 | D2: MERNIY ANATOLIY GRIGOREVICH | E2: 10:01:06:01:02:5074 | F2: Богистон | G2: 257 | H2: 2500 | I2: 2500 | J2: =I2-H2 -> 0 | K2: 135 | L2: 31.84 | M2: Ҳадя шартномаси 20-331 08/05/03 | N2: =I2*P2/100 -> 1750000 | O2: =K2*300 -> 40500 | P2: 70000 | Q2: =N2+O2 -> 1790500
A3: 2 | B3: 2 | C3: 1 | D3: NASIROVA FOTIMA XAMIDULLAYEVNA | E3: 10:01:06:01:02:5136 | F3: Х Турсункулов | G3: 259 | H3: 2400 | I3: 3200 | J3: =I3-H3 -> 800 | K3: 675 | L3: 115.49 | M3: Олди-сотди шартномаси 927 27/02/03 | N3: =I3*P3/100 -> 2240000 | O3: =K3*300 -> 202500 | P3: 70000 | Q3: =N3+O3 -> 2442500
A4: 3 | B4: 4 | C4: 1 | D4: TULAGANOV AXMADJON TAGIROVICH | E4: 10:01:06:01:02:5075 | F4: Богистон | G4: 261 | H4: 1390 | I4: 1390 | J4: =I4-H4 -> 0 | K4: 588 | L4: 231.64 | M4: Олди-сотди шартномаси 2,02102E+14 27/12/21 | N4: =I4*P4/100 -> 973000 | O4: =K4*300 -> 176400 | P4: 70000 | Q4: =N4+O4 -> 1149400
A5: 4 | B5: 5 | C5: 1 | D5: YAFUNYAYEV MURAD FARIDOVICH | E5: 10:01:06:01:02:5076 | F5: Богистон | G5: 263 | H5: 4900 | I5: 5098 | J5: =I5-H5 -> 198 | K5: 311 | L5: 257.26 | M5: Олди-сотди шартномаси 12-901 14/10/99 | N5: =I5*P5/100 -> 2549000 | O5: =K5*300 -> 93300 | P5: 50000 | Q5: =N5+O5 -> 2642300
H6: =SUM(H2:H5) -> 11190 | I6: =SUM(I2:I5) -> 12188 | J6: =SUM(J2:J5) -> 998 | K6: =SUM(K2:K5) -> 1709 | L6: =SUM(L2:L5) -> 636.23 | M6: =SUM(M2:M5) -> 0 | N6: =SUM(N2:N5) -> 7512000 | O6: =SUM(O2:O5) -> 512700 | ... Q6: =SUM(Q2:Q5) -> 8024700
A7: 5 | B7: 8 | C7: 2 | D7: XUSNITDINOV TAXIRDJAN XUDAYBERGENOVICH | E7: 10:01:06:01:02:5123 | F7: Богистон | G7: 275 | H7: 636 | I7: 636 | J7: =I7-H7 -> 0 | K7: 413 | L7: 105.19 | M7: Қонун бўйича ворислик ҳақида гувоҳнома 2-6149 04/12/90 | N7: =I7*P7/100 -> 318000 | O7: =K7*300 -> 123900 | P7: 50000 | Q7: =N7+O7 -> 441900
A8: 6 | B8: 9 | C8: 2 | D8: XUSNITDINOV DILSHOD TAXIRJANOVICH | E8: 10:01:06:01:02:5123/01 | F8: Богистон | G8: 275б | H8: 398 | I8: 398 | J8: =I8-H8 -> 0 | K8: 134 | L8: 66.01 | M8: Ҳадя шартномаси 2,019E+14 02/07/19 | N8: =I8*P8/100 -> 199000 | O8: =K8*300 -> 40200 | P8: 50000 | Q8: =N8+O8 -> 239200
A9: 7 | B9: 10 | C9: 2 | D9: ACHILOVA GULBAXOR RIXSIYEVNA | E9: 10:01:06:01:02:5078/01 | F9: Богистон | G9: 275г | H9: 300 | I9: 300 | J9: =I9-H9 -> 0 | K9: 117 | L9: 52.72 | M9: Ҳадя шартномаси 2,01901E+14 15/02/19 | N9: =I9*P9/100 -> 150000 | O9: =K9*300 -> 35100 | P9: 50000 | Q9: =N9+O9 -> 185100
A10: 8 | B10: 11 | C10: 2 | D10: XAITMUXAMEDOVA DILORAM TOXIRJONOVNA | E10: 10:01:06:01:02:5154 | F10: Богистон | G10: 275в | H10: 391 | I10: 391 | J10: =I10-H10 -> 0 | K10: 233 | L10: 89.46 | M10: Ҳадя шартномаси 2,02002E+14 13/11/20 | N10: =I10*P10/100 -> 195500 | O10: =K10*300 -> 69900 | P10: 50000 | Q10: =N10+O10 -> 265400
A11: 9 | B11: 12 | C11: 2 | D11: KARIMOVA MALIKA TAXIRDJANOVNA | E11: 10:01:06:01:02:5078 | F11: Богистон | G11: 275а | H11: 845 | I11: 845 | J11: =I11-H11 -> 0 | K11: 276 | L11: 80.59 | M11: Ҳадя шартномаси 2,01901E+14 15/02/19 | N11: =I11*P11/100 -> 422500 | O11: =K11*300 -> 82800 | P11: 50000 | Q11: =N11+O11 -> 505300
A12: 10 | B12: 13 | C12: 2 | D12: XUDJAMURATOV ALISHER AVLAYEVICH | E12: 10:01:06:01:02:5156 | F12: Богистон | G12: 275д | H12: 600 | I12: 659 | J12: =I12-H12 -> 59 | K12: 22 | L12: 16.24 | M12: Олди-сотди шартномаси 2,02002E+14 16/09/20 | N12: =I12*P12/100 -> 329500 | O12: =K12*300 -> 6600 | P12: 50000 | Q12: =N12+O12 -> 336100
A13: 11 | B13: 14 | C13: 2 | D13: XASHIMOV XABIBULLA XASANOVICH | E13: 10:01:06:01:02:5079 | F13: Богистон | G13: 277 | H13: 754 | I13: 779 | J13: =I13-H13 -> 25 | K13: 470 | L13: 217.57 | M13: Ҳадя шартномаси Р-р1-2975 09.10.2003 | N13: =I13*P13/100 -> 623200 | O13: =K13*300 -> 141000 | P13: 80000 | Q13: =N13+O13 -> 764200
A14: 12 | B14: 15 | C14: 2 | D14: XASHIMOV ABDURAXMON ABDUKASIMOVICH | E14: 10:01:06:01:02:5144 | F14: Богистон | G14: 279а | H14: 535 | I14: 535 | J14: =I14-H14 -> 0 | K14: 222 | L14: 85.84 | M14: Ҳадя шартномаси 1-3869 13/10/16 | N14: =I14*P14/100 -> 428000 | O14: =K14*300 -> 66600 | P14: 80000 | Q14: =N14+O14 -> 494600
A15: 13 | B15: 16 | C15: 2 | D15: XASHIMOV MURAT XUSANOVICH | E15: 10:01:06:01:02:5141 | F15: Богистон | G15: 281 | H15: 1093 | I15: 1093 | J15: =I15-H15 -> 0 | K15: 460 | L15: 182.68 | M15: Қонун бўйича ворислик ҳақида гувоҳнома 2,019E+14 16/09/19 | N15: =I15*P15/100 -> 546500 | O15: =K15*300 -> 138000 | P15: 50000 | Q15: =N15+O15 -> 684500
A16: 14 | B16: 17 | C16: 2 | D16: AXRAROV SANJAR YAXYAYEVICH | E16: 10:01:06:01:02:5080 | F16: Богистон | G16: 279 | H16: 1265 | I16: 2509 | J16: =I16-H16 -> 1244 | K16: 653 | L16: 68.49 | M16: Келишув битими 2,019E+14 06/08/19 | N16: =I16*P16/100 -> 1630850 | O16: =K16*300 -> 195900 | P16: 65000 | Q16: =N16+O16 -> 1826750
A17: 15 | B17: 18 | C17: 2 | D17: XALILOV ABDUSAMAT ABDUJALILOVICH | E17: 10:01:06:01:02:5132 | F17: Богистон | G17: 283а | H17: 600 | I17: 600 | J17: =I17-H17 -> 0 | K17: 167 | L17: 30.53 | M17: Васиятнома бўйича меросга бўлган ҳуқуқ ҳақидаги гувоҳномаси 1-441 16/02/17 | N17: =I17*P17/100 -> 480000 | O17: =K17*300 -> 50100 | P17: 80000 | Q17: =N17+O17 -> 530100
A18: 16 | B18: 19 | C18: 2 | D18: XALILOV ABDUSATTOR ABDUJALILOVICH | E18: 10:01:06:01:02:5081 | F18: Богистон | G18: 283 | H18: 2114 | I18: 2114 | J18: =I18-H18 -> 0 | K18: 556 | L18: 233.3 | M18: Қонун бўйича ворислик ҳақида гувоҳнома 1-439 16/02/17 | N18: =I18*P18/100 -> 1057000 | O18: =K18*300 -> 166800 | P18: 50000 | Q18: =N18+O18 -> 1223800
A19: 17 | B19: 26 | C19: 2 | D19: BIRYUKOVA ROZA GLIMYANOVNA | E19: 10:01:06:01:02:5135 | F19: Фозилтепа | G19: 244 | H19: 1010 | I19: 1010 | J19: =I19-H19 -> 0 | K19: 228 | L19: 76.5 | M19: қарори 227 28/03/18 | N19: =I19*P19/100 -> 505000 | O19: =K19*300 -> 68400 | P19: 50000 | Q19: =N19+O19 -> 573400
H20: =SUM(H7:H19) -> 10541 | I20: =SUM(I7:I19) -> 11869 | J20: =SUM(J7:J19) -> 1328 | K20: =SUM(K7:K19) -> 3951 | L20: =SUM(L7:L19) -> 1305.12 | M20: =SUM(M7:M19) -> 0 | N20: =SUM(N7:N19) -> 6885050 | O20: =SUM(O7:O19) -> 1185300 | ... Q20: =SUM(Q7:Q19) -> 8070350
A21: 18 | C21: 3 | D21: ASAMOVA NOZIMA AKMALOVNA | E21: 10:01:06:01:02:5073 | F21: Боғобод | G21: 180 | H21: 1020 | I21: 1020 | K21: 390 | N21: =I21*P21/100 -> 510000 | O21: =K21*300 -> 117000 | P21: 50000 | Q21: =N21+O21 -> 627000
A22: 19 | C22: 3 | D22: ASAMOVA NAILYA NASIROVNA | E22: 10:01:06:01:02:5161 | F22: Боғобод | G22: 180а | K22: 236 | N22: =I22*P22/100 -> 0 | O22: =K22*300 -> 70800 | P22: 50000 | Q22: =N22+O22 -> 70800
H23: =SUM(H21:H22) -> 1020 | I23: =SUM(I21:I22) -> 1020 | J23: =SUM(J21:J22) -> 0 | K23: =SUM(K21:K22) -> 626 | L23: =SUM(L21:L22) -> 0 | M23: =SUM(M21:M22) -> 0 | N23: =SUM(N21:N22) -> 510000 | O23: =SUM(O21:O22) -> 187800 | ... Q23: =SUM(Q21:Q22) -> 697800
A24: 20 | B24: 68 | C24: 8 | D24: XAMIDOV KOZIM DJURAYEVICH | E24: 10:01:06:01:02:5115 | F24: Богистон, туп 5 | G24: 97 | H24: 734 | I24: 734 | J24: =I24-H24 -> 0 | K24: 378 | L24: 121.55 | M24: Ҳадя шартномаси 1-4258 03/12/15 | N24: =I24*P24/100 -> 367000 | O24: =K24*300 -> 113400 | P24: 50000 | Q24: =N24+O24 -> 480400
A25: 21 | B25: 69 | C25: 8 | D25: MUMINOV SAGDULLA MOVLANOVICH | E25: 10:01:06:01:02:5036 | F25: ул. Богистон, дом | G25: 121 | H25: 520 | I25: 520 | J25: =I25-H25 -> 0 | K25: 305 | L25: 132.96 | M25: туман ижроия қўмитаси қарори 11-3/2 23/01/92 | N25: =I25*P25/100 -> 260000 | O25: =K25*300 -> 91500 | P25: 50000 | Q25: =N25+O25 -> 351500
A26: 22 | B26: 70 | C26: 8 | D26: MIRXADIYEV SHERZOD MIRAXMADOVICH | E26: 10:01:06:01:02:5037/01 | F26: ул. Богистон, дом | G26: 40а | H26: 380 | I26: 380 | J26: =I26-H26 -> 0 | K26: 240 | L26: 110.6 | M26: Олди-сотди шартномаси 7253 11/12/07 | N26: =I26*P26/100 -> 190000 | O26: =K26*300 -> 72000 | P26: 50000 | Q26: =N26+O26 -> 262000
A27: 23 | B27: 71 | C27: 8 | D27: YAKUBDJANOVA MOXIRA MELSOVNA | E27: 10:01:06:01:02:5037 | F27: ул. Богистон, дом | G27: 40 | H27: 500 | I27: 500 | J27: =I27-H27 -> 0 | K27: 333 | L27: 255.79 | M27: Олди-сотди шартномаси 15-576 11/06/10 | N27: =I27*P27/100 -> 250000 | O27: =K27*300 -> 99900 | P27: 50000 | Q27: =N27+O27 -> 349900
A28: 24 | B28: 73 | C28: 8 | D28: XODIYEV RAXMAT MAXKAMOVICH | E28: 10:01:06:01:02:5120 | F28: Богистон | G28: 63 | H28: 286 | I28: 286 | J28: =I28-H28 -> 0 | K28: 141 | L28: 93.53 | M28: қарори 612 05/10/18 | N28: =I28*P28/100 -> 143000 | O28: =K28*300 -> 42300 | P28: 50000 | Q28: =N28+O28 -> 185300
H29: =SUM(H24:H28) -> 2420 | I29: =SUM(I24:I28) -> 2420 | J29: =SUM(J24:J28) -> 0 | K29: =SUM(K24:K28) -> 1397 | L29: =SUM(L24:L28) -> 714.43 | M29: =SUM(M24:M28) -> 0 | N29: =SUM(N24:N28) -> 1210000 | O29: =SUM(O24:O28) -> 419100 | ... Q29: =SUM(Q24:Q28) -> 1629100
A30: 25 | B30: 5 | C30: 9 | D30: SHERXANOV SHAHZOD RAVSHAN O‘G‘LI | E30: 10:01:06:01:02:5052 | F30: Богистон | G30: 67 | H30: 600 | I30: 600 | J30: =I30-H30 -> 0 | K30: 407 | L30: 201.6 | M30: Олди-сотди шартномаси 2,019E+14 27/12/19 | N30: =I30*P30/100 -> 300000 | O30: =K30*300 -> 122100 | P30: 50000 | Q30: =N30+O30 -> 422100
A31: 26 | B31: 74 | C31: 9 | D31: YAKUBOV SAMUK NABIYEVICH | E31: 10:01:06:01:02:5028 | F31: Богистон | G31: 107 | H31: 660 | I31: 660 | J31: =I31-H31 -> 0 | K31: 404 | L31: 110.21 | M31: Қонун бўйича ворислик ҳақида гувоҳнома 8-532 30/01/06 | N31: =I31*P31/100 -> 330000 | O31: =K31*300 -> 121200 | P31: 50000 | Q31: =N31+O31 -> 451200
A32: 27 | B32: 75 | C32: 9 | D32: YAKUBOV SAMUK NABIYEVICH | E32: 10:01:06:01:02:5101 | F32: Богистон | G32: 105 | H32: 1592 | I32: 663 | J32: =I32-H32 -> -929 | K32: 146 | L32: 72.12 | M32: қарори 314/26 26/12/91 | N32: =I32*P32/100 -> 331500 | O32: =K32*300 -> 43800 | P32: 50000 | Q32: =N32+O32 -> 375300
A33: 28 | B33: 76 | C33: 9 | D33: YAKUBOV SHOKIRJON SAMUKOVICH | E33: 10:01:06:01:02:5101/01 | F33: Богистон | G33: 105а | H33: 1592 | I33: 929 | J33: =I33-H33 -> -663 | K33: 465 | L33: 224.02 | M33: Ҳадя шартномаси 2,019E+14 21/01/19 | N33: =I33*P33/100 -> 464500 | O33: =K33*300 -> 139500 | P33: 50000 | Q33: =N33+O33 -> 604000
A34: 29 | B34: 77 | C34: 9 | D34: BABAJANOV BEHZOD POLVANNAZIROVICH | E34: 10:01:06:01:02:5003 | F34: Богистон | G34: 103 | H34: 488 | I34: 488 | J34: =I34-H34 -> 0 | K34: 93 | L34: 39.4 | M34: Олди-сотди шартномаси 2,02102E+14 16/12/21 | N34: =I34*P34/100 -> 244000 | O34: =K34*300 -> 27900 | P34: 50000 | Q34: =N34+O34 -> 271900
A35: 30 | B35: 78 | C35: 9 | D35: YAKUBDJANOVA OZODAGUL DJARKINOVNA | E35: 10:01:06:01:02:5001 | F35: Богистон | G35: 101 | H35: 600 | I35: 670 | J35: =I35-H35 -> 70 | K35: 134 | L35: 43.11 | M35: Олди-сотди шартномаси 4710 07/09/18 | N35: =I35*P35/100 -> 335000 | O35: =K35*300 -> 40200 | P35: 50000 | Q35: =N35+O35 -> 375200
A36: 31 | B36: 79 | C36: 9 | D36: BAKAYEVA XODJINISA NABIYEVNA | E36: 10:01:06:01:02:5002 | F36: Богистон | G36: 1 | H36: 558 | I36: 572 | J36: =I36-H36 -> 14 | K36: 295 | L36: 99.59 | M36: Курилиш шартномаси 1336р9-232 19/02/92 | N36: =I36*P36/100 -> 343200 | O36: =K36*300 -> 88500 | P36: 60000 | Q36: =N36+O36 -> 431700
A37: 32 | B37: 80 | C37: 9 | D37: ACHILOV ABDURASHID RIXSIVAYEVICH | E37: 10:01:06:01:02:5095 | F37: Богистон | G37: 3 | H37: 1310 | I37: 1310 | J37: =I37-H37 -> 0 | K37: 639 | L37: 269.67 | M37: Васиятнома бўйича ворислик ҳақида гувоҳномаси 1-1714 30/04/12 | N37: =I37*P37/100 -> 786000 | O37: =K37*300 -> 191700 | P37: 60000 | Q37: =N37+O37 -> 977700
A38: 33 | B38: 81 | C38: 9 | D38: Ачилов Абдурахман | E38: 10:01:06:01:02:5138 | F38: Богистон | G38: 38 (34) | H38: 885 | I38: 904 | J38: =I38-H38 -> 19 | K38: 508 | L38: 125.99 | M38: а карори.277-1-23.14 | N38: =I38*P38/100 -> 452000 | O38: =K38*300 -> 152400 | P38: 50000 | Q38: =N38+O38 -> 604400
A39: 34 | B39: 82 | C39: 9 | D39: KADIROV RUSTAM SULTANOVICH | E39: 10:01:06:01:02:5160 | F39: Богистон | G39: 7а | H39: 430 | I39: 430 | J39: =I39-H39 -> 0 | K39: 179 | L39: 28.6 | M39: Олди-сотди шартномаси 2,02102E+14 15/10/21 | N39: =I39*P39/100 -> 215000 | O39: =K39*300 -> 53700 | P39: 50000 | Q39: =N39+O39 -> 268700
A40: 35 | B40: 86 | C40: 9 | D40: ASAMUTDINOV BAXTIYOR KOMILOVICH | E40: 10:01:07:01:01:5168 | F40: Богистон | G40: 11 | H40: 631 | I40: 631 | J40: =I40-H40 -> 0 | K40: 227 | L40: 107.48 | M40: Қонун бўйича ворислик ҳақида гувоҳнома 1-2024 19/04/13 | N40: =I40*P40/100 -> 315500 | O40: =K40*300 -> 68100 | P40: 50000 | Q40: =N40+O40 -> 383600
...

Sheet Нотурар
A1: тр | B1: Лот | C1: Мулк эгаси | D1: Кўчаси | E1: Уй рақами | F1: Кадастр рақами | G1: Хужжати | H1: Хужжат бўйича Ер майдони, кв.м. | I1: Сотка | J1: Қурилиш ости кв.м. | K1: Захват кв.м. | L1: Снос харажатлари ($100 000)
A2: 1 | B2: 3 | C2: ЧП "GULSHAN JILOSI" | D2: Фозилтепа | E2: 178 | F2: 10:01:06:01:02:0019 | G2: Олди сотди шартномаси 07.08.2012 й № 2/2833, Фуқаролик ишлари бўйича Тошкент шахар судининг қарори 17.03.2015 й № 10-1520/3172 | H2: 639 | I2: =H2/100 -> 6.39 | J2: 678 | L2: =I2*100000 -> 639000
A3: 2 | B3: 3 | C3: MIRSOATOV UBAYDULLO ABDULLO O‘G‘LI | D3: Фозилтепа | E3: 178 | F3: 10:01:06:01:02:0031 | G3: Олди сотди шартномаси 06.03.2019 й № 201900061001688. | I3: =H3/100 -> 0 | J3: 67 | L3: =J3*1000 -> 67000
H4: =SUM(H2:H3) -> 639 | I4: =SUM(I2:I3) -> 6.39 | J4: =SUM(J2:J3) -> 745 | K4: =SUM(K2:K3) -> 0 | L4: =SUM(L2:L3) -> 706000
A5: 3 | B5: 4 | C5: SIDIKOV BAXODIR AKMALOVICH | D5: Фозилтепа | E5: 178 | F5: 10:01:06:01:02:0032 | G5: Олди сотди шартномаси 03.06.2021 й № 202102108003387. | H5: 1045 | I5: =H5/100 -> 10.45 | J5: 892 | L5: =I5*100000 -> 1045000
H6: =SUM(H5) -> 1045 | I6: =SUM(I5) -> 10.45 | J6: =SUM(J5) -> 892 | K6: =SUM(K5) -> 0 | L6: =SUM(L5) -> 1045000
A7: 4 | B7: 5 | C7: OOO "AKSAVA" | D7: Фозилтепа, | E7: 34 | F7: 10:01:06:01:02:0008 | G7: Решение хакима №970 от 27.08.2001г. | H7: 1000 | I7: =H7/100 -> 10 | K7: 7 | L7: =I7*100000 -> 1000000
A8: 5 | B8: 5 | C8: ООО "PROF AVTO GARANT" | D8: Фозилтепа | F8: 10:01:06:01:02:0003 | G8: Решение Хокима №104 от 30.01.2017г. | H8: 333 | I8: =H8/100 -> 3.33 | L8: =I8*100000 -> 333000
A9: 6 | B9: 5 | C9: ЧП 'MTP GARANT AGROMASH SERVIS' | D9: Фозилтепа, | E9: 34 | F9: 10:01:06:01:02:0009 | G9: Государственный ордер №12 от 23.07.2015г. | H9: 4285 | I9: =H9/100 -> 42.85 | L9: =I9*100000 -> 4285000
A10: 7 | B10: 5 | C10: ГП "Спецавтообъединение Главного управления здравоохранения г.Ташкента" | D10: Фозилтепа, | E10: 34 | F10: 10:01:06:01:02:0005 | G10: Приказ №65 от 16.02.1995г. Приказ №289 от 13.10.2017г. | H10: 42507 | I10: =H10/100 -> 425.07 | L10: 8000000
A11: 8 | B11: 5 | C11: ООО "TOSHKENT SHAHAR SUV TA`MINOTI" | D11: Фозилтепа, | E11: 30 | F11: 10:01:06:01:02:0021 | G11: Учтепа туман хокимининг карори 10.03.2017 й. № 238 | H11: 14394 | I11: =H11/100 -> 143.94 | L11: 7000000
H12: =SUM(H7:H11) -> 62519 | I12: =SUM(I7:I11) -> 625.19 | J12: =SUM(J7:J11) -> 0 | K12: =SUM(K7:K11) -> 7 | L12: =SUM(L7:L11) -> 20618000
A13: 9 | B13: 8 | C13: G‘OFUROV SA’DULLA TAXIR O‘G‘LI | D13: Богистон кўчаси | E13: 99а | H13: 436 | I13: =H13/100 -> 4.36 | J13: 175 | L13: =I13*100000 -> 436000
A14: 10 | B14: 8 | C14: OOO "RESTAVRATOR UNIVERSAL" | D14: Богистон кўчаси | E14: 99Б | H14: 662 | I14: =H14/100 -> 6.62 | J14: 217 | L14: =I14*100000 -> 662000
H15: =SUM(H13:H14) -> 1098 | I15: =SUM(I13:I14) -> 10.98 | J15: =SUM(J13:J14) -> 392 | K15: =SUM(K13:K14) -> 0 | L15: =SUM(L13:L14) -> 1098000
A16: 11 | B16: 9 | C16: ЧП "VLAVAD RENT SERVIS" | D16: Фозилтепа, | E16: 42 | F16: 10:01:06:01:02:0040 | G16: Государственный ордер №247 от 06.09.2006г. | H16: 2328 | I16: =H16/100 -> 23.28 | L16: =I16*100000 -> 2328000
H17: =SUM(H16) -> 2328 | I17: =SUM(I16) -> 23.28 | J17: =SUM(J16) -> 0 | K17: =SUM(K16) -> 0 | L17: =SUM(L16) -> 2328000
A18: 12 | B18: 12 | C18: ATABAYEV ALISHER QADAMOVICH | D18: Богистон, | E18: 4а | F18: 10:01:06:01:02:0022 | G18: Договор купли-продажи №01/08 от 13.08.2020г. | H18: 211 | I18: =H18/100 -> 2.11 | L18: =I18*100000 -> 211000
A19: 13 | B19: 12 | C19: ЧП "DE LYUKS STAR" | D19: Богистон, | E19: 4а | F19: 10:01:06:01:02:0038 | G19: решение №145 от 13.03.2015г. | H19: 3663 | I19: =H19/100 -> 36.63 | L19: =I19*100000 -> 3663000
A20: 14 | B20: 12 | C20: MUXAMEDOV BEXZOD NIGMATULLAYEVICH | D20: Богистон, | E20: 4б | F20: 10:01:06:01:02:0047 | G20: Решение Хокима №78 от 12.02.2015г. | H20: 1751 | I20: =H20/100 -> 17.51 | L20: =I20*100000 -> 1751000
A21: 15 | B21: 12 | C21: ООО 'RAVSHANJON-UNIPROM ' | D21: Богистон, | E21: 4а | F21: 10:01:06:01:02:0054 | G21: Договор купли-продажи №4986 от 19.08.2014г.акт приемки в эксплуатацию завершенных строительством (реконструкцией) зданий и сооружений №28941511 от 19.03.2021г. | H21: 516 | I21: =H21/100 -> 5.16 | L21: =I21*100000 -> 516000
A22: 16 | B22: 12 | C22: ООО "RAVSHANJON-UNIPROM" | D22: Богистон, | E22: 4а | F22: 10:01:06:01:02:0029 | G22: Решение хакима №42 от 14.02.2008г. | H22: 2152 | I22: =H22/100 -> 21.52 | L22: =I22*100000 -> 2152000
A23: 17 | B23: 12 | C23: ООО "ERDON-SERVIS" | D23: Богистон, | E23: 4е | F23: 10:01:06:01:02:0025 | G23: Решение хакима №12 от 13.01.2009г. | H23: 3600 | I23: =H23/100 -> 36 | L23: =I23*100000 -> 3600000
H24: =SUM(H18:H23) -> 11893 | I24: =SUM(I18:I23) -> 118.93 | J24: =SUM(J18:J23) -> 0 | K24: =SUM(K18:K23) -> 0 | L24: =SUM(L18:L23) -> 11893000
A25: 18 | B25: 14 | C25: ООО 'QODIRBEK' | D25: МКАД | F25: 10:01:06:01:02:0013 | G25: Решение хакима №261 от 12.10.2006г. Решение Хокима №1182 от 28.12.2017г. | H25: 1150 | I25: =H25/100 -> 11.5 | L25: =I25*100000 -> 1150000
H26: =SUM(H25) -> 1150 | I26: =SUM(I25) -> 11.5 | J26: =SUM(J25) -> 0 | K26: =SUM(K25) -> 0 | L26: =SUM(L25) -> 1150000
C27: Жами: | H27: =H4+H6+H12+H15+H17+H24+H26 -> 80672 | I27: =I4+I6+I12+I15+I17+I24+I26 -> 806.72 | J27: =J4+J6+J12+J15+J17+J24+J26 -> 2029 | K27: =K4+K6+K12+K15+K17+K24+K26 -> 7 | L27: =L4+L6+L12+L15+L17+L24+L26 -> 38838000
B29: Компенсация берилмайдиган нотурар объектлар
C30: Мулк эгаси | D30: Кўчаси | E30: Уй рақами | F30: Кадастр рақами | G30: Хужжати | H30: Хужжат бўйича Ер майдони, кв.м. | I30: Сотка
B31: "DRENAJLAR VA KOLLEKTORLARNI TA'MIRLASH VA SAQLASH IXTISOSLASHTIRILGAN BOSHKARMASI"DAVLAT MUASSASAS | D31: Фозилтепа | E31: 178 | F31: 10:01:06:01:02:0049 | G31: Мехнаткашлар депутатлариТошкент шахар советининг ижроия комитетининг қарори 01.07.1969 й № 192, Тошкент шахар совет халқ депутатлари комитетининг қарори 06.03.1987 й № 155/5, Акмал Икромов туман хокимининг қарори 29.10.1999 й № 1493. | H31: 1013 | I31: =H31/100 -> 10.13
B32: XUKUMAT OB'EKLARIDA XIZMAT KO'RSATISH BO'YICHA MAXSUS BOSHQARMA | D32: Фозилтепа | E32: 178 | F32: 10:01:06:01:02:0014 | G32: Ўзбекистон Республикаси Вазирлар Махкамасининг фармойиши 20.03.2003 й № 166-ф | H32: 19805 | I32: =H32/100 -> 198.05
B33: Сход граждан махалли 'CHO'PON OTA' | D33: Богистон, | E33: 5 | F33: 10:01:06:01:02:0052 | G33: Договор аренды земельного участка №1-14-1-0283-12 от 26.08.2012г. | H33: 1011 | I33: =H33/100 -> 10.11
C34: ГУП "SUVSOZ" | D34: Фозилтепа, | E34: 42 | F34: 10:01:06:01:02:0039 | G34: Решение №708/33 от 04.12.1987г. Государственный ордер подтверждающий права собственности №16 от 05.05.2020г. | H34: 5308 | I34: =H34/100 -> 53.08
C36: G‘AFURJONOV SHAHZOD ALISHER O‘G‘LI | D36: Фозилтепа | F36: 10:01:06:01:02:0017 | G36: Олди сотди шартномаси 05.02.2021 й № 202101915001388. | H36: 1660 | I36: =H36/100 -> 16.6
C37: XAMIDOVA PARIDA KABILOVNA | D37: Богобод | E37: 269,271а,273 | F37: 10:01:06:01:02:0055 | G37: Учтепа туман хокимининг қарори 27.05.2016 й № 398 | H37: 4144 | I37: =H37/100 -> 41.44
C38: ООО "TURON MEROS" | D38: Фозилтепа | E38: 178 | F38: 10:01:06:01:02:0058 | G38: Тошкент шахар хокими 01.06.2021 й № 650 | H38: 15000 | I38: =H38/100 -> 150
C39: ООО "SOFIYA QANDOLAT" | D39: Фозилтепа | F39: 10:01:06:01:02:0057 | G39: Тошкент шахар хокими 07.04.2021 й № 386 | H39: 8000 | I39: =H39/100 -> 80
C40: ООО "MADINA-MUXLISA STAR" (Парк) | D40: Фозилтепа, | E40: 251 | F40: 10:01:06:01:02:0016 | G40: Учтепа туман хокими қарори 14.12.2017 й № 1140 | H40: 45200 | I40: =H40/100 -> 452
C41: Жами: | H41: =SUM(H27:H34) -> 107809 | I41: =SUM(I27:I34) -> 1078.09
