Workbook

Sheet Свод
A1: Учтепа сити лойиҳасини амалга ошириш учун дастлабки таҳлилий сарф-харажатлар
A2: ҲИСОБ КИТОБИ
A4: Харажатлар номи | B4: Сони | C4: Суммаси
A5: Турар-жойларни кўчириш билан боғлиқ компенсация харажатлари | B5: =Турар!A157 -> 151 | C5: =Турар!Q158 -> 76359453
A6: Нотурар-жойларни кўчириш билан боғлиқ компенсация харажатлари | B6: 16 | C6: =Нотурар!L20 -> 37980000
A7: Вазирлар Маҳкамасининг 2024 йил 10 июльдаги 414-сонли қарорига асосан дирекция томонидан давлат объектларини кўчириш мажбурияти харажатлари | B7: 5 | C7: 15000000
A8: Дирекция сақлаш ва бошқа сарф-харажатлари | C8: 3000000
A9: Қўшимча харажатлар (1-2 %) | C9: =(C8+C7+C6+C5)*1.5% -> 1985091.8
A10: Ички инфротузилма | C10: 7100000
A11: Яшил майдон | C11: 3500000
A12: Жами харажатлар: | C12: =SUM(C5:C11) -> 1.4492454e+08

Sheet Нотурар
A1: Учтепа тумани Катта Чўпонота махалласидаги нотурар объектлар
A2: Тартиб рақами | B2: Карта рақами | C2: Мулк эгаси | D2: Кўчаси | E2: Уй рақами | F2: Кадастр рақами | G2: Хужжати | H2: Хужжат бўйича Ер майдони, кв.м. | I2: Сотка | J2: Қурилиш ости кв.м. | K2: Захват кв.м. | L2: Снос харажатлари ($100 000)
A3: 1 | B3: 134 | C3: ООО 'QODIRBEK' | D3: МКАД | F3: 10:01:06:01:02:0013 | G3: Решение хакима №261 от 12.10.2006г. Решение Хокима №1182 от 28.12.2017г. | H3: 1150 | I3: =H3/100 -> 11.5 | L3: =I3*100000 -> 1150000
A4: 2 | B4: 136 | C4: ATABAYEV ALISHER QADAMOVICH | D4: Богистон, | E4: 4а | F4: 10:01:06:01:02:0022 | G4: Договор купли-продажи №01/08 от 13.08.2020г. | H4: 211 | I4: =H4/100 -> 2.11 | L4: =I4*100000 -> 211000
A5: 3 | B5: 137 | C5: ЧП "DE LYUKS STAR" | D5: Богистон, | E5: 4а | F5: 10:01:06:01:02:0038 | G5: решение №145 от 13.03.2015г. | H5: 3663 | I5: =H5/100 -> 36.63 | L5: =I5*100000 -> 3663000
A6: 4 | B6: 138 | C6: MUXAMEDOV BEXZOD NIGMATULLAYEVICH | D6: Богистон, | E6: 4б | F6: 10:01:06:01:02:0047 | G6: Решение Хокима №78 от 12.02.2015г. | H6: 1751 | I6: =H6/100 -> 17.51 | L6: =I6*100000 -> 1751000
A7: 5 | B7: 139 | C7: ООО 'RAVSHANJON-UNIPROM ' | D7: Богистон, | E7: 4а | F7: 10:01:06:01:02:0054 | G7: Договор купли-продажи №4986 от 19.08.2014г.акт приемки в эксплуатацию завершенных строительством (реконструкцией) зданий и сооружений №28941511 от 19.03.2021г. | H7: 516 | I7: =H7/100 -> 5.16 | L7: =I7*100000 -> 516000
A8: 6 | B8: 140 | C8: ООО "RAVSHANJON-UNIPROM" | D8: Богистон, | E8: 4а | F8: 10:01:06:01:02:0029 | G8: Решение хакима №42 от 14.02.2008г. | H8: 2152 | I8: =H8/100 -> 21.52 | L8: =I8*100000 -> 2152000
A9: 7 | B9: 144 | C9: ООО "UCHTEPA AKSAZ" | D9: МКАД, | E9: 3а | F9: 10:01:06:01:02:0030 | G9: Решение хакима №1266 от 22.12.2003г. | H9: 240 | I9: =H9/100 -> 2.4 | K9: 27 | L9: =I9*100000 -> 240000
A10: 8 | B10: 155 | C10: ЧП "VLAVAD RENT SERVIS" | D10: Фозилтепа, | E10: 42 | F10: 10:01:06:01:02:0040 | G10: Государственный ордер №247 от 06.09.2006г. | H10: 2328 | I10: =H10/100 -> 23.28 | L10: =I10*100000 -> 2328000
A11: 9 | B11: 157 | C11: OOO "AKSAVA" | D11: Фозилтепа, | E11: 34 | F11: 10:01:06:01:02:0008 | G11: Решение хакима №970 от 27.08.2001г. | H11: 1000 | I11: =H11/100 -> 10 | K11: 7 | L11: =I11*100000 -> 1000000
A12: 10 | B12: 158 | C12: ООО "PROF AVTO GARANT" | D12: Фозилтепа | F12: 10:01:06:01:02:0003 | G12: Решение Хокима №104 от 30.01.2017г. | H12: 333 | I12: =H12/100 -> 3.33 | L12: =I12*100000 -> 333000
A13: 11 | B13: 159 | C13: ЧП 'MTP GARANT AGROMASH SERVIS' | D13: Фозилтепа, | E13: 34 | F13: 10:01:06:01:02:0009 | G13: Государственный ордер №12 от 23.07.2015г. | H13: 4285 | I13: =H13/100 -> 42.85 | L13: =I13*100000 -> 4285000
A14: 12 | B14: 160 | C14: ООО "ERDON-SERVIS" | D14: Богистон, | E14: 4е | F14: 10:01:06:01:02:0025 | G14: Решение хакима №12 от 13.01.2009г. | H14: 3600 | I14: =H14/100 -> 36 | L14: =I14*100000 -> 3600000
A15: 13 | B15: 20 | C15: ЧП "GULSHAN JILOSI" | D15: Фозилтепа | E15: 178 | F15: 10:01:06:01:02:0019 | G15: Олди сотди шартномаси 07.08.2012 й № 2/2833, Фуқаролик ишлари бўйича Тошкент шахар судининг қарори 17.03.2015 й № 10-1520/3172 | H15: 639 | I15: =H15/100 -> 6.39 | J15: 678 | L15: =I15*100000 -> 639000
A16: 14 | B16: 22 | C16: MIRSOATOV UBAYDULLO ABDULLO O‘G‘LI | D16: Фозилтепа | E16: 178 | F16: 10:01:06:01:02:0031 | G16: Олди сотди шартномаси 06.03.2019 й № 201900061001688. | I16: =H16/100 -> 0 | J16: 67 | L16: =J16*1000 -> 67000
A17: 15 | B17: 23 | C17: SIDIKOV BAXODIR AKMALOVICH | D17: Фозилтепа | E17: 178 | F17: 10:01:06:01:02:0032 | G17: Олди сотди шартномаси 03.06.2021 й № 202102108003387. | H17: 1045 | I17: =H17/100 -> 10.45 | J17: 892 | L17: =I17*100000 -> 1045000
A18: 16 | B18: 2 | C18: ГП "Спецавтообъединение Главного управления здравоохранения г.Ташкента" | D18: Фозилтепа, | E18: 34 | F18: 10:01:06:01:02:0005 | G18: Приказ №65 от 16.02.1995г. Приказ №289 от 13.10.2017г. | H18: 42507 | I18: =H18/100 -> 425.07 | L18: 8000000
A19: 17 | B19: 1 | C19: ООО "TOSHKENT SHAHAR SUV TA`MINOTI" | D19: Фозилтепа, | E19: 30 | F19: 10:01:06:01:02:0021 | G19: Учтепа туман хокимининг карори 10.03.2017 й. № 238 | H19: 14394 | I19: =H19/100 -> 143.94 | L19: 7000000
C20: Жами: | H20: =SUM(H3:H29) -> 24573 | I20: =SUM(I3:I29) -> 245.73 | K20: =SUM(K3:K29) -> 117 | L20: =SUM(L3:L19) -> 37980000
A22: Компенсация берилмайдиган ҳамада бузилмайдиган нотурар объектлар
A23: Тартиб рақами | B23: Карта рақами | C23: Мулк эгаси | D23: Кўчаси | E23: Уй рақами | F23: Кадастр рақами | G23: Хужжати | H23: Хужжат бўйича Ер майдони, кв.м. | I23: Сотка | K23: Захват кв.м. | L23: Снос харажатлари ($100 000)
A24: 18 | B24: 21 | C24: "DRENAJLAR VA KOLLEKTORLARNI TA'MIRLASH VA SAQLASH IXTISOSLASHTIRILGAN BOSHKARMASI"DAVLAT MUASSASAS | D24: Фозилтепа | E24: 178 | F24: 10:01:06:01:02:0049 | G24: Мехнаткашлар депутатлариТошкент шахар советининг ижроия комитетининг қарори 01.07.1969 й № 192, Тошкент шахар совет халқ депутатлари комитетининг қарори 06.03.1987 й № 155/5, Акмал Икромов туман хокимининг қарори 29.10.1999 й № 1493. | H24: 1013 | I24: =H24/100 -> 10.13
A25: 19 | B25: 24 | C25: XUKUMAT OB'EKLARIDA XIZMAT KO'RSATISH BO'YICHA MAXSUS BOSHQARMA | D25: Фозилтепа | E25: 178 | F25: 10:01:06:01:02:0014 | G25: Ўзбекистон Республикаси Вазирлар Махкамасининг фармойиши 20.03.2003 й № 166-ф | H25: 19805 | I25: =H25/100 -> 198.05
A26: 20 | B26: 135 | C26: Сход граждан махалли 'CHO'PON OTA' | D26: Богистон, | E26: 5 | F26: 10:01:06:01:02:0052 | G26: Договор аренды земельного участка №1-14-1-0283-12 от 26.08.2012г. | H26: 1011 | I26: =H26/100 -> 10.11
A27: 21 | B27: 156 | C27: ГУП "SUVSOZ" | D27: Фозилтепа, | E27: 42 | F27: 10:01:06:01:02:0039 | G27: Решение №708/33 от 04.12.1987г. Государственный ордер подтверждающий права собственности №16 от 05.05.2020г. | H27: 5308 | I27: =H27/100 -> 53.08
A29: 1 | B29: 28 | C29: G‘AFURJONOV SHAHZOD ALISHER O‘G‘LI | D29: Фозилтепа | F29: 10:01:06:01:02:0017 | G29: Олди сотди шартномаси 05.02.2021 й № 202101915001388. | H29: 1660 | I29: =H29/100 -> 16.6 | J29: 52 | K29: 83
A30: 2 | B30: 7 | C30: XAMIDOVA PARIDA KABILOVNA | D30: Богобод | E30: 269,271а,273 | F30: 10:01:06:01:02:0055 | G30: Учтепа туман хокимининг қарори 27.05.2016 й № 398 | H30: 4144 | I30: =H30/100 -> 41.44 | J30: 1791
A31: 3 | B31: 25 | C31: ООО "TURON MEROS" | D31: Фозилтепа | E31: 178 | F31: 10:01:06:01:02:0058 | G31: Тошкент шахар хокими 01.06.2021 й № 650 | H31: 15000 | I31: =H31/100 -> 150
A32: 4 | B32: 27 | C32: ООО "SOFIYA QANDOLAT" | D32: Фозилтепа | F32: 10:01:06:01:02:0057 | G32: Тошкент шахар хокими 07.04.2021 й № 386 | H32: 8000 | I32: =H32/100 -> 80 | J32: 7628
A33: 5 | B33: 29 | C33: ООО "MADINA-MUXLISA STAR" (Парк) | D33: Фозилтепа, | E33: 251 | F33: 10:01:06:01:02:0016 | G33: Учтепа туман хокими қарори 14.12.2017 й № 1140 | H33: 45200 | I33: =H33/100 -> 452
A34: 23 | C34: Жами: | H34: =SUM(H19:H27) -> 41531 | I34: =SUM(I19:I27) -> 415.31 | K34: =SUM(K19:K27) -> 0

Sheet Турар
A1: Учтепа тумани Катта Чўпонота махалласидаги турар уй жойлар
A2: № | B2: К/р | D2: Мулкдор | E2: Кадастр рақами | F2: Кўча | G2: Уй рақами | H2: Хужжат бўйича Ер майдони, кв.м. | I2: Умумий ер майдони кв.м. | J2: Ўзбошимча ер майдони кв.м. | K2: Қурилиш оости майдони кв.м. | L2: Яшаш майдони кв.м. | M2: Хуқуқ тури | N2: Ер нархи кв.м. $ 500-800 | O2: Бино нархи $ 300
A3: 1 | B3: 1 | C3: 1 | D3: MERNIY ANATOLIY GRIGOREVICH | E3: 10:01:06:01:02:5074 | F3: Богистон | G3: 257 | H3: 2500 | I3: 2500 | J3: =I3-H3 -> 0 | K3: 135 | L3: 31.84 | M3: Ҳадя шартномаси 20-331 08/05/03 | N3: =I3*P3/100 -> 1750000 | O3: =K3*300 -> 40500 | P3: 70000 | Q3: =N3+O3 -> 1790500
A4: 2 | B4: 2 | C4: 1 | D4: NASIROVA FOTIMA XAMIDULLAYEVNA | E4: 10:01:06:01:02:5136 | F4: Х Турсункулов | G4: 259 | H4: 2400 | I4: 3200 | J4: =I4-H4 -> 800 | K4: 675 | L4: 115.49 | M4: Олди-сотди шартномаси 927 27/02/03 | N4: =I4*P4/100 -> 2240000 | O4: =K4*300 -> 202500 | P4: 70000 | Q4: =N4+O4 -> 2442500
A5: 3 | B5: 4 | C5: 1 | D5: TULAGANOV AXMADJON TAGIROVICH | E5: 10:01:06:01:02:5075 | F5: Богистон | G5: 261 | H5: 1390 | I5: 1390 | J5: =I5-H5 -> 0 | K5: 588 | L5: 231.64 | M5: Олди-сотди шартномаси 2,02102E+14 27/12/21 | N5: =I5*P5/100 -> 973000 | O5: =K5*300 -> 176400 | P5: 70000 | Q5: =N5+O5 -> 1149400
A6: 4 | B6: 5 | C6: 1 | D6: YAFUNYAYEV MURAD FARIDOVICH | E6: 10:01:06:01:02:5076 | F6: Богистон | G6: 263 | H6: 4900 | I6: 5098 | J6: =I6-H6 -> 198 | K6: 311 | L6: 257.26 | M6: Олди-сотди шартномаси 12-901 14/10/99 | N6: =I6*P6/100 -> 2549000 | O6: =K6*300 -> 93300 | P6: 50000 | Q6: =N6+O6 -> 2642300
A7: 5 | B7: 8 | C7: 2 | D7: XUSNITDINOV TAXIRDJAN XUDAYBERGENOVICH | E7: 10:01:06:01:02:5123 | F7: Богистон | G7: 275 | H7: 636 | I7: 636 | J7: =I7-H7 -> 0 | K7: 413 | L7: 105.19 | M7: Қонун бўйича ворислик ҳақида гувоҳнома 2-6149 04/12/90 | N7: =I7*P7/100 -> 318000 | O7: =K7*300 -> 123900 | P7: 50000 | Q7: =N7+O7 -> 441900
A8: 6 | B8: 9 | C8: 2 | D8: XUSNITDINOV DILSHOD TAXIRJANOVICH | E8: 10:01:06:01:02:5123/01 | F8: Богистон | G8: 275б | H8: 398 | I8: 398 | J8: =I8-H8 -> 0 | K8: 134 | L8: 66.01 | M8: Ҳадя шартномаси 2,019E+14 02/07/19 | N8: =I8*P8/100 -> 199000 | O8: =K8*300 -> 40200 | P8: 50000 | Q8: =N8+O8 -> 239200
A9: 7 | B9: 10 | C9: 2 | D9: ACHILOVA GULBAXOR RIXSIYEVNA | E9: 10:01:06:01:02:5078/01 | F9: Богистон | G9: 275г | H9: 300 | I9: 300 | J9: =I9-H9 -> 0 | K9: 117 | L9: 52.72 | M9: Ҳадя шартномаси 2,01901E+14 15/02/19 | N9: =I9*P9/100 -> 150000 | O9: =K9*300 -> 35100 | P9: 50000 | Q9: =N9+O9 -> 185100
A10: 8 | B10: 11 | C10: 2 | D10: XAITMUXAMEDOVA DILORAM TOXIRJONOVNA | E10: 10:01:06:01:02:5154 | F10: Богистон | G10: 275в | H10: 391 | I10: 391 | J10: =I10-H10 -> 0 | K10: 233 | L10: 89.46 | M10: Ҳадя шартномаси 2,02002E+14 13/11/20 | N10: =I10*P10/100 -> 195500 | O10: =K10*300 -> 69900 | P10: 50000 | Q10: =N10+O10 -> 265400
A11: 9 | B11: 12 | C11: 2 | D11: KARIMOVA MALIKA TAXIRDJANOVNA | E11: 10:01:06:01:02:5078 | F11: Богистон | G11: 275а | H11: 845 | I11: 845 | J11: =I11-H11 -> 0 | K11: 276 | L11: 80.59 | M11: Ҳадя шартномаси 2,01901E+14 15/02/19 | N11: =I11*P11/100 -> 422500 | O11: =K11*300 -> 82800 | P11: 50000 | Q11: =N11+O11 -> 505300
A12: 10 | B12: 13 | C12: 2 | D12: XUDJAMURATOV ALISHER AVLAYEVICH | E12: 10:01:06:01:02:5156 | F12: Богистон | G12: 275д | H12: 600 | I12: 659 | J12: =I12-H12 -> 59 | K12: 22 | L12: 16.24 | M12: Олди-сотди шартномаси 2,02002E+14 16/09/20 | N12: =I12*P12/100 -> 329500 | O12: =K12*300 -> 6600 | P12: 50000 | Q12: =N12+O12 -> 336100
A13: 11 | B13: 14 | C13: 2 | D13: XASHIMOV XABIBULLA XASANOVICH | E13: 10:01:06:01:02:5079 | F13: Богистон | G13: 277 | H13: 754 | I13: 779 | J13: =I13-H13 -> 25 | K13: 470 | L13: 217.57 | M13: Ҳадя шартномаси Р-р1-2975 09.10.2003 | N13: =I13*P13/100 -> 623200 | O13: =K13*300 -> 141000 | P13: 80000 | Q13: =N13+O13 -> 764200
A14: 12 | B14: 15 | C14: 2 | D14: XASHIMOV ABDURAXMON ABDUKASIMOVICH | E14: 10:01:06:01:02:5144 | F14: Богистон | G14: 279а | H14: 535 | I14: 535 | J14: =I14-H14 -> 0 | K14: 222 | L14: 85.84 | M14: Ҳадя шартномаси 1-3869 13/10/16 | N14: =I14*P14/100 -> 428000 | O14: =K14*300 -> 66600 | P14: 80000 | Q14: =N14+O14 -> 494600
A15: 13 | B15: 16 | C15: 2 | D15: XASHIMOV MURAT XUSANOVICH | E15: 10:01:06:01:02:5141 | F15: Богистон | G15: 281 | H15: 1093 | I15: 1093 | J15: =I15-H15 -> 0 | K15: 460 | L15: 182.68 | M15: Қонун бўйича ворислик ҳақида гувоҳнома 2,019E+14 16/09/19 | N15: =I15*P15/100 -> 546500 | O15: =K15*300 -> 138000 | P15: 50000 | Q15: =N15+O15 -> 684500
A16: 14 | B16: 17 | C16: 2 | D16: AXRAROV SANJAR YAXYAYEVICH | E16: 10:01:06:01:02:5080 | F16: Богистон | G16: 279 | H16: 1265 | I16: 2509 | J16: =I16-H16 -> 1244 | K16: 653 | L16: 68.49 | M16: Келишув битими 2,019E+14 06/08/19 | N16: =I16*P16/100 -> 1630850 | O16: =K16*300 -> 195900 | P16: 65000 | Q16: =N16+O16 -> 1826750
A17: 15 | B17: 18 | C17: 2 | D17: XALILOV ABDUSAMAT ABDUJALILOVICH | E17: 10:01:06:01:02:5132 | F17: Богистон | G17: 283а | H17: 600 | I17: 600 | J17: =I17-H17 -> 0 | K17: 167 | L17: 30.53 | M17: Васиятнома бўйича меросга бўлган ҳуқуқ ҳақидаги гувоҳномаси 1-441 16/02/17 | N17: =I17*P17/100 -> 480000 | O17: =K17*300 -> 50100 | P17: 80000 | Q17: =N17+O17 -> 530100
A18: 16 | B18: 19 | C18: 2 | D18: XALILOV ABDUSATTOR ABDUJALILOVICH | E18: 10:01:06:01:02:5081 | F18: Богистон | G18: 283 | H18: 2114 | I18: 2114 | J18: =I18-H18 -> 0 | K18: 556 | L18: 233.3 | M18: Қонун бўйича ворислик ҳақида гувоҳнома 1-439 16/02/17 | N18: =I18*P18/100 -> 1057000 | O18: =K18*300 -> 166800 | P18: 50000 | Q18: =N18+O18 -> 1223800
A19: 17 | B19: 26 | C19: 2 | D19: BIRYUKOVA ROZA GLIMYANOVNA | E19: 10:01:06:01:02:5135 | F19: Фозилтепа | G19: 244 | H19: 1010 | I19: 1010 | J19: =I19-H19 -> 0 | K19: 228 | L19: 76.5 | M19: қарори 227 28/03/18 | N19: =I19*P19/100 -> 505000 | O19: =K19*300 -> 68400 | P19: 50000 | Q19: =N19+O19 -> 573400
A20: 18 | C20: 3 | D20: ASAMOVA NOZIMA AKMALOVNA | E20: 10:01:06:01:02:5073 | F20: Боғобод | G20: 180 | H20: 1020 | I20: 1020 | K20: 390 | N20: =I20*P20/100 -> 510000 | O20: =K20*300 -> 117000 | P20: 50000 | Q20: =N20+O20 -> 627000
A21: 19 | C21: 3 | D21: ASAMOVA NAILYA NASIROVNA | E21: 10:01:06:01:02:5161 | F21: Боғобод | G21: 180а | K21: 236 | N21: =I21*P21/100 -> 0 | O21: =K21*300 -> 70800 | P21: 50000 | Q21: =N21+O21 -> 70800
D22: Mannapov Ibroxim Abdunazarovich | F22: Богистон | G22: 261а | H22: 428 | I22: =H22 -> 428 | J22: =I22-H22 -> 0
D23: KARIMOV FAXRIDDIN TULYAGANOVICH | F23: Богистон | G23: 271 | H23: 2214 | I23: =H23 -> 2214 | J23: =I23-H23 -> 0
D24: Жами: | H24: =SUM(H3:H19) -> 21731 | I24: =SUM(I3:I19) -> 24057 | J24: =SUM(J3:J19) -> 2326 | K24: =SUM(K3:K19) -> 5660 | L24: =SUM(L3:L19) -> 1941.35 | N24: =SUM(N3:N21) -> 14907050 | O24: =SUM(O3:O21) -> 1885800 | Q24: =N24+O24 -> 16792850
J25: =I25-H25 -> 0 | P25: 50000 | Q25: =N25+O25 -> 0
A26: 20 | B26: 3 | C26: 10 | D26: XAMEDOV ZAFAR IRGASHEVICH | E26: 10:01:06:01:02:5150 | F26: Богистон | G26: 75а | H26: 487 | I26: 487 | J26: =I26-H26 -> 0 | K26: 220 | L26: 36.4 | M26: қарори 327 29/11/18 | N26: =I26*P26/100 -> 243500 | O26: =K26*300 -> 66000 | P26: 50000 | Q26: =N26+O26 -> 309500
A27: 21 | B27: 4 | C27: 10 | D27: XODJAYEV MURODJON KARIMBERDIYEVICH | E27: 10:01:06:01:02:5139 | F27: Богистон | G27: 65 | H27: 600 | I27: 591 | J27: =I27-H27 -> -9 | K27: 110 | L27: 11.2 | M27: Олди-сотди шартномаси 2,02002E+14 22/05/20 | N27: =I27*P27/100 -> 295500 | O27: =K27*300 -> 33000 | P27: 50000 | Q27: =N27+O27 -> 328500
A28: 22 | B28: 5 | C28: 9 | D28: SHERXANOV SHAHZOD RAVSHAN O‘G‘LI | E28: 10:01:06:01:02:5052 | F28: Богистон | G28: 67 | H28: 600 | I28: 600 | J28: =I28-H28 -> 0 | K28: 407 | L28: 201.6 | M28: Олди-сотди шартномаси 2,019E+14 27/12/19 | N28: =I28*P28/100 -> 300000 | O28: =K28*300 -> 122100 | P28: 50000 | Q28: =N28+O28 -> 422100
A29: 23 | B29: 6 | C29: 10 | D29: RASHIDOV ZIYOVIDDIN NAIMOVICH | E29: 10:01:06:01:02:5039 | F29: Богистон | G29: 69 | H29: 941 | I29: 941 | J29: =I29-H29 -> 0 | K29: 340 | L29: 130.68 | M29: Қонун бўйича ворислик ҳақида гувоҳнома 2,02202E+14 17/02/22 | N29: =I29*P29/100 -> 470500 | O29: =K29*300 -> 102000 | P29: 50000 | Q29: =N29+O29 -> 572500
A30: 24 | B30: 7 | C30: 10 | D30: ATABAYEVA DILORAM IRGASHEVNA | E30: 10:01:06:01:02:5059 | F30: Богистон | G30: 71 | H30: 482 | I30: 482 | J30: =I30-H30 -> 0 | K30: 350 | L30: 164.96 | M30: Ҳадя шартномаси 10-201 23/05/07 | N30: =I30*P30/100 -> 241000 | O30: =K30*300 -> 105000 | P30: 50000 | Q30: =N30+O30 -> 346000
A31: 25 | B31: 8 | C31: 10 | D31: XAMEDOV RAVSHAN IRGASHEVICH | E31: 10:01:06:01:02:5060 | F31: Богистон | G31: 73 | H31: 837 | I31: 837 | J31: =I31-H31 -> 0 | K31: 339 | L31: 197.16 | M31: қарори 80 26/02/10 | N31: =I31*P31/100 -> 418500 | O31: =K31*300 -> 101700 | P31: 50000 | Q31: =N31+O31 -> 520200
A32: 26 | B32: 9 | C32: 10 | D32: MUMINOV ISMATULLA MOVLANOVICH | E32: 10:01:06:02:02:5099 | F32: Богистон | G32: 61б | H32: 600 | I32: 582 | J32: =I32-H32 -> -18 | K32: 353 | L32: 83.64 | M32: Олди-сотди шартномаси 21-1246 30/06/00 | N32: =I32*P32/100 -> 291000 | O32: =K32*300 -> 105900 | P32: 50000 | Q32: =N32+O32 -> 396900
A33: 27 | B33: 10 | C33: 10 | D33: ABDUVAXIDOVA MUXAYO ABDUVALIYEVNA | E33: 10:01:06:01:02:5055 | F33: Богистон | G33: 61 | H33: 600 | I33: 598 | J33: =I33-H33 -> -2 | K33: 163 | L33: 73.41 | M33: Қонун бўйича ворислик ҳақида гувоҳнома 1-2337 25/06/18 | N33: =I33*P33/100 -> 299000 | O33: =K33*300 -> 48900 | P33: 50000 | Q33: =N33+O33 -> 347900
A34: 28 | B34: 11 | C34: 10 | D34: XAMEDOV ZAFAR IRGASHEVICH | E34: 10:01:06:01:02:5061 | F34: Богистон | G34: 75 | H34: 888 | I34: 888 | J34: =I34-H34 -> 0 | K34: 504 | L34: 228.01 | M34: қарори 79 сонли 26/02/10 | N34: =I34*P34/100 -> 444000 | O34: =K34*300 -> 151200 | P34: 50000 | Q34: =N34+O34 -> 595200
A35: 29 | B35: 12 | C35: 10 | D35: KUSHAKOV ARTIK AXMADJANOVICH | E35: 10:01:06:01:02:5051 | F35: Богистон | G35: 59 | H35: 600 | I35: 600 | J35: =I35-H35 -> 0 | K35: 244 | L35: 82.69 | M35: Олди-сотди шартномаси 1-299 10/01/00 | N35: =I35*P35/100 -> 300000 | O35: =K35*300 -> 73200 | P35: 50000 | Q35: =N35+O35 -> 373200
A36: 30 | B36: 13 | C36: 10 | D36: AXUNDJANOVA NILUFAR MAXMUDJANOVNA | E36: 10:01:06:01:02:5128 | F36: Богистон | G36: 77 | H36: 645 | I36: 645 | J36: =I36-H36 -> 0 | K36: 218 | L36: 60.36 | M36: Олди-сотди шартномаси 2,02202E+14 04/10/22 | N36: =I36*P36/100 -> 322500 | O36: =K36*300 -> 65400 | P36: 50000 | Q36: =N36+O36 -> 387900
A37: 31 | B37: 14 | C37: 10 | D37: UMAROV ABDURASHID UKTAMOVICH | E37: 10:01:06:01:02:5049 | F37: Богистон | G37: 57 | H37: 575 | I37: 575 | J37: =I37-H37 -> 0 | K37: 302 | L37: 115.79 | M37: Ҳадя шартномаси 1990 01/04/00 | N37: =I37*P37/100 -> 287500 | O37: =K37*300 -> 90600 | P37: 50000 | Q37: =N37+O37 -> 378100
A38: 32 | B38: 15 | C38: 10 | D38: UMAROV MUMIN UKTAMOVICH | E38: 10:01:06:01:02:5134 | F38: Богистон | G38: 55 | H38: 628 | I38: 628 | J38: =I38-H38 -> 0 | K38: 442 | L38: 74.77 | M38: қарори 612 05/10/18 | N38: =I38*P38/100 -> 314000 | O38: =K38*300 -> 132600 | P38: 50000 | Q38: =N38+O38 -> 446600
A39: 33 | B39: 16 | C39: 10 | D39: ILXAMOV IKRAM XXX | E39: 10:01:06:01:02:5147 | F39: Богистон | G39: 79 | H39: 600 | I39: 534 | J39: =I39-H39 -> -66 | K39: 254 | L39: 100.3 | M39: қарори 380/11 15/10/91 | N39: =I39*P39/100 -> 267000 | O39: =K39*300 -> 76200 | P39: 50000 | Q39: =N39+O39 -> 343200
A40: 34 | B40: 17 | C40: 10 | D40: MUSAYEV RIXSIBAY XODJIAKBAROVICH | E40: 10:01:06:01:02:5083 | F40: Богистон, туп 5 | G40: 51 | H40: 600 | I40: 611 | J40: =I40-H40 -> 11 | K40: 452 | L40: 190.55 | M40: Учтепа тумани ҳокимининг қарори 1179 10/08/99 | N40: =I40*P40/100 -> 305500 | O40: =K40*300 -> 135600 | P40: 50000 | Q40: =N40+O40 -> 441100
...

Sheet Турар Лотлар 
A1: № | B1: К/р | C1: Мулкдор | D1: Кадастр рақами | E1: Лот рақами | F1: Кўча | G1: Уй рақами | H1: Хужжат бўйича Ер майдони, кв.м. | I1: Умумий ер майдони кв.м. | J1: Ўзбошимча ер майдони кв.м. | K1: Қурилиш оости майдони кв.м. | L1: Яшаш майдони кв.м. | M1: Хуқуқ тури | N1: Ер нархи кв.м. $ 500-800 | O1: Бино нархи $ 300 | Q1: Компенсиация суммаси тахминий | R1: Лот майдони сотих | S1: Хар бир сотих | T1: 1 сўтиҳ нархи | U1: Тушум
A2: 1 | B2: 123 | C2: NURITDINOV KAMAL SALAXITDINOVICH | D2: 10:01:06:01:02:5070 | E2: 1 | F2: Богистон | G2: 102 | H2: 990 | I2: 990 | J2: =I2-H2 -> 0 | K2: 357 | L2: 201.82 | M2: Курилиш шартномаси 1367р-р4-3522 02/06/92 | N2: =I2*P2/100 -> 495000 | O2: =K2*300 -> 107100 | P2: 50000 | Q2: =N2+O2 -> 602100
A3: 2 | B3: 124 | C3: XAKIMOV ABDUMUTAL RASHIDOVICH | D3: 10:01:06:01:02:5072 | E3: 1 | F3: Богистон | G3: 106 | H3: 1759 | I3: 1759 | J3: =I3-H3 -> 0 | K3: 477 | L3: 236.99 | M3: Курилиш шартномаси 1369 р-р № 10-2609 02/06/92 | N3: =I3*P3/100 -> 1055400 | O3: =K3*300 -> 143100 | P3: 60000 | Q3: =N3+O3 -> 1198500
A4: 3 | B4: 125 | C4: XAKIMOV JAVLONBEK ABDUMUTALOVICH | D4: 10:01:06:01:02:5103 | E4: 1 | F4: Богистон | G4: 131 | H4: 600 | I4: 600 | J4: =I4-H4 -> 0 | K4: 226 | L4: 122.29 | M4: Ҳадя шартномаси 3173 23/06/09 | N4: =I4*P4/100 -> 390000 | O4: =K4*300 -> 67800 | P4: 65000 | Q4: =N4+O4 -> 457800
A5: 4 | B5: 126 | C5: KUSHAKOV LUTFULLA FAYZULLAYEVICH | D5: 10:01:06:01:02:5096 | E5: 1 | F5: Богистон | G5: 105 | H5: 739 | I5: 739 | J5: =I5-H5 -> 0 | K5: 427 | L5: 211.65 | M5: Ҳадя шартномаси 2,02102E+14 19/10/21 | N5: =I5*P5/100 -> 369500 | O5: =K5*300 -> 128100 | P5: 50000 | Q5: =N5+O5 -> 497600
A6: 5 | B6: 127 | C6: ADILOV KOMAL KOBILOVICH | D6: 10:01:06:01:02:5094 | E6: 1 | F6: Богистон | G6: 110 | H6: 523 | I6: 523 | J6: =I6-H6 -> 0 | K6: 195 | L6: 99.21 | M6: қарори 434 26/09/08 | N6: =I6*P6/100 -> 261500 | O6: =K6*300 -> 58500 | P6: 50000 | Q6: =N6+O6 -> 320000
A7: 6 | B7: 128 | C7: ADILOV MAMURJAN KABILOVICH | D7: 10:01:06:01:02:5097 | E7: 1 | F7: Богистон | G7: 112 | H7: 600 | I7: 600 | J7: =I7-H7 -> 0 | K7: 391 | L7: 174.5 | M7: Учтепа тумани ҳокимининг қарори 275 01/06/09 | N7: =I7*P7/100 -> 360000 | O7: =K7*300 -> 117300 | P7: 60000 | Q7: =N7+O7 -> 477300
A8: 7 | B8: 129 | C8: ADILOV MELS KABILOVICH | D8: 10:01:06:01:02:5004 | E8: 1 | F8: Богистон | G8: 116 | H8: 600 | I8: 575 | J8: =I8-H8 -> -25 | K8: 332 | L8: 132.64 | M8: қарори 794 15/07/03 | N8: =I8*P8/100 -> 345000 | O8: =K8*300 -> 99600 | P8: 60000 | Q8: =N8+O8 -> 444600
A9: 8 | B9: 130 | C9: ADILOV MAXAMATJAN KABILOVICH | D9: 10:01:06:01:02:5137/01 | E9: 1 | F9: Богистон | G9: 114а | H9: 1387 | I9: 794 | J9: =I9-H9 -> -593 | K9: 421 | L9: 109.27 | M9: Ҳадя шартномаси 15-347 27/04/06 | N9: =I9*P9/100 -> 397000 | O9: =K9*300 -> 126300 | P9: 50000 | Q9: =N9+O9 -> 523300
A10: 9 | B10: 131 | C10: QOBILOV SARDORJON SOBIT O‘G‘LI | D10: 10:01:06:01:02:5137 | E10: 1 | F10: Богистон | G10: 114 | H10: 1387 | I10: 586 | J10: =I10-H10 -> -801 | K10: 234 | L10: 98.78 | M10: Қонун бўйича меросга бўлган ҳуқуқ ҳақида гувоҳнома 2,02303E+14 23/02/23 | N10: =I10*P10/100 -> 293000 | O10: =K10*300 -> 70200 | P10: 50000 | Q10: =N10+O10 -> 363200
A11: 10 | B11: 132 | C11: ZIYAMUXAMEDOV SHUKRULLA ZAKIROVICH | D11: 10:01:06:02:02:5166 | E11: 1 | F11: Богистон | G11: 110а | H11: 600 | I11: 600 | J11: =I11-H11 -> 0 | K11: 460 | L11: 198.34 | M11: Олди-сотди шартномаси 15-254 30/03/06 | N11: =I11*P11/100 -> 390000 | O11: =K11*300 -> 138000 | P11: 65000 | Q11: =N11+O11 -> 528000
A12: 11 | B12: 133 | C12: IMAMOV OLIMJON TOIROVICH | D12: 10:01:06:01:02:5035 | E12: 1 | F12: Богистон | G12: 4 | H12: 1037 | I12: 1037 | J12: =I12-H12 -> 0 | K12: 494 | L12: 180.1 | M12: Қонун бўйича ворислик ҳақида гувоҳнома 1-3450 15/10/18 | N12: =I12*P12/100 -> 622200 | O12: =K12*300 -> 148200 | P12: 60000 | Q12: =N12+O12 -> 770400
A13: 12 | B13: 134 | C13: ООО 'QODIRBEK' | D13: 10:01:06:01:02:0013 | E13: 1 | F13: МКАД | H13: 1150 | I13: =H13/100 -> 11.5 | M13: Решение хакима №261 от 12.10.2006г. Решение Хокима №1182 от 28.12.2017г. | Q13: =H13*1000 -> 1150000
C14: Лот жами: | E14: =E13 -> 1 | H14: =SUM(H2:H13) -> 11372 | I14: =SUM(I2:I13) -> 8814.5 | J14: =SUM(J2:J13) -> -1419 | K14: =SUM(K2:K13) -> 4014 | L14: =SUM(L2:L13) -> 1765.59 | Q14: =SUM(Q2:Q13) -> 7332800 | R14: 136 | S14: =Q14/R14 -> 53917.647 | T14: 100000 | U14: =R14*T14 -> 13600000
T15: 70000 | U15: =R15*T15 -> 0
A16: 13 | B16: 115 | C16: ACHILOV ABDUAZIZ ABDURAXMANOVICH | D16: 10:01:06:01:02:5066 | E16: 2 | F16: Богистон | G16: 88 | H16: 600 | I16: 617 | J16: =I16-H16 -> 17 | K16: 366 | L16: 209.7 | M16: Олди-сотди шартномаси 1195 11/04/01 | N16: =I16*P16/100 -> 308500 | O16: =K16*300 -> 109800 | P16: 50000 | Q16: =N16+O16 -> 418300 | T16: 70000 | U16: =R16*T16 -> 0
A17: 14 | B17: 116 | C17: XAMDAMOV ATXAM XXX | D17: 10:01:06:01:02:5118 | E17: 2 | F17: Богистон, проезд 1 | G17: 90а | H17: 600 | I17: 608 | J17: =I17-H17 -> 8 | K17: 280 | L17: 108.02 | M17: Курилиш шартномаси №1561 р-р 25-603 27/08/95 | N17: =I17*P17/100 -> 304000 | O17: =K17*300 -> 84000 | P17: 50000 | Q17: =N17+O17 -> 388000 | T17: 70000 | U17: =R17*T17 -> 0
A18: 15 | B18: 117 | C18: AZIMOV KAMILJON SATTAROVICH | D18: 10:01:06:01:02:5146 | E18: 2 | F18: Богистон | G18: 92 | H18: 830 | I18: 830 | J18: =I18-H18 -> 0 | K18: 359 | L18: 298.2 | M18: қарори 612 05/10/18 | N18: =I18*P18/100 -> 415000 | O18: =K18*300 -> 107700 | P18: 50000 | Q18: =N18+O18 -> 522700 | T18: 70000 | U18: =R18*T18 -> 0
A19: 16 | B19: 118 | C19: UMAROVA MASHKURA USMANOVNA | D19: 10:01:06:02:02:5155 | E19: 2 | F19: Х Турсункулов | G19: 98 | H19: 600 | I19: 600 | J19: =I19-H19 -> 0 | K19: 217 | L19: 148.38 | M19: Олди-сотди шартномаси 2-15 06/01/95 | N19: =I19*P19/100 -> 300000 | O19: =K19*300 -> 65100 | P19: 50000 | Q19: =N19+O19 -> 365100 | T19: 70000 | U19: =R19*T19 -> 0
A20: 17 | B20: 119 | C20: UMAROV BAXTIYAR UKTAMOVICH | D20: 10:01:06:02:02:5212 | E20: 2 | F20: Богистон | G20: 99 | H20: 600 | I20: 600 | J20: =I20-H20 -> 0 | K20: 365 | L20: 279.5 | M20: Ҳадя шартномаси 15-1063 16/12/98 | N20: =I20*P20/100 -> 300000 | O20: =K20*300 -> 109500 | P20: 50000 | Q20: =N20+O20 -> 409500 | T20: 70000 | U20: =R20*T20 -> 0
A21: 18 | B21: 120 | C21: UMAROV BAXODIR UKTAMOVICH | D21: 10:01:06:02:02:5156 | E21: 2 | F21: Богистон | G21: 98 | H21: 600 | I21: 600 | J21: =I21-H21 -> 0 | K21: 249 | L21: 105.8 | M21: Курилиш шартномаси 1350 р-р2-1736 08/04/92 | N21: =I21*P21/100 -> 300000 | O21: =K21*300 -> 74700 | P21: 50000 | Q21: =N21+O21 -> 374700 | T21: 70000 | U21: =R21*T21 -> 0
A22: 19 | B22: 121 | C22: UMAROV RUSTAM UKTAMOVICH | D22: 10:01:06:01:02:5116 | E22: 2 | F22: Богистон | G22: 100 | H22: 600 | I22: 600 | J22: =I22-H22 -> 0 | K22: 349 | L22: 166.26 | M22: Тошкент шаҳар ҳокимининг қарори 380/11 15/10/91 | N22: =I22*P22/100 -> 300000 | O22: =K22*300 -> 104700 | P22: 50000 | Q22: =N22+O22 -> 404700 | T22: 70000 | U22: =R22*T22 -> 0
A23: 20 | B23: 122 | C23: UMAROV ULUGBEK UKTAMOVICH | D23: 10:01:06:01:02:5158 | E23: 2 | F23: Богистон | G23: 94 | H23: 566 | I23: 566 | J23: =I23-H23 -> 0 | K23: 245 | L23: 148.9 | M23: қарори 2262 02/08/19 | N23: =I23*P23/100 -> 283000 | O23: =K23*300 -> 73500 | P23: 50000 | Q23: =N23+O23 -> 356500 | T23: 70000 | U23: =R23*T23 -> 0
C24: Лот жами: | E24: =E23 -> 2 | H24: =SUM(H16:H23) -> 4996 | I24: =SUM(I16:I23) -> 5021 | J24: =SUM(J16:J23) -> 25 | K24: =SUM(K16:K23) -> 2430 | L24: =SUM(L16:L23) -> 1464.76 | Q24: =SUM(Q16:Q23) -> 3239500 | R24: 50 | S24: =Q24/R24 -> 64790 | T24: 70000 | U24: =R24*T24 -> 3500000
T25: 70000 | U25: =R25*T25 -> 0
A26: 21 | B26: 42 | C26: XAMDAMOV ALIDJAN ANVAROVICH | D26: 10:01:06:01:02:5152 | E26: 3 | F26: Богистон | G26: 72 | H26: 725 | I26: 725 | J26: =I26-H26 -> 0 | K26: 315 | L26: 65.34 | M26: қарори 1415 10/05/19 | N26: =I26*P26/100 -> 362500 | O26: =K26*300 -> 94500 | P26: 50000 | Q26: =N26+O26 -> 457000 | T26: 70000 | U26: =R26*T26 -> 0
A27: 22 | B27: 43 | C27: ABDURASULOV FAXRIDDIN ABDUSAMATOVICH | D27: 10:01:06:01:02:5155 | E27: 3 | F27: Богистон | G27: 72а | H27: 217 | I27: 217 | J27: =I27-H27 -> 0 | K27: 150 | L27: 47.14 | M27: қарори 2388 02/08/19 | N27: =I27*P27/100 -> 108500 | O27: =K27*300 -> 45000 | P27: 50000 | Q27: =N27+O27 -> 153500 | T27: 70000 | U27: =R27*T27 -> 0
A28: 23 | B28: 109 | C28: AZIMOV DILSHOD SHUKUROVICH | D28: 10:01:06:01:02:5062 | E28: 3 | F28: Богистон | G28: 76 | H28: 600 | I28: 600 | J28: =I28-H28 -> 0 | K28: 102 | L28: 38.48 | M28: О/С шарт.Р-р8-3719.2 | N28: =I28*P28/100 -> 300000 | O28: =K28*300 -> 30600 | P28: 50000 | Q28: =N28+O28 -> 330600 | T28: 70000 | U28: =R28*T28 -> 0
A29: 24 | B29: 110 | C29: ABDULLAYEVA MAXMUDA GAPPAROVNA | D29: 10:01:06:01:02:5067 | E29: 3 | F29: Богистон | G29: 91 | H29: 588 | I29: 588 | J29: =I29-H29 -> 0 | K29: 301 | L29: 175.9 | M29: Олди-сотди шартномаси 12-1595 23/04/92 | N29: =I29*P29/100 -> 294000 | O29: =K29*300 -> 90300 | P29: 50000 | Q29: =N29+O29 -> 384300 | T29: 70000 | U29: =R29*T29 -> 0
A30: 25 | B30: 111 | C30: Умаров Алишер Уктамович | D30: 10:01:06:02:02:5150 | E30: 3 | F30: Х Турсункулов | G30: 90 | H30: 600 | I30: 651 | J30: =I30-H30 -> 51 | K30: 290 | L30: 137.7 | M30: Курилиш шартномаси 1352 р2-1733 14/04/92 | N30: =I30*P30/100 -> 325500 | O30: =K30*300 -> 87000 | P30: 50000 | Q30: =N30+O30 -> 412500 | T30: 70000 | U30: =R30*T30 -> 0
A31: 26 | B31: 112 | C31: GULAMOV MAXAMADRASUL MAXAMADJANOVICH | D31: 10:01:06:01:02:5065 | E31: 3 | F31: Богистон | G31: 86а | H31: 600 | I31: 600 | J31: =I31-H31 -> 0 | K31: 129 | L31: 62.85 | M31: О/С шарт.Р-р1-14523 28/07/05 | N31: =I31*P31/100 -> 300000 | O31: =K31*300 -> 38700 | P31: 50000 | Q31: =N31+O31 -> 338700 | T31: 70000 | U31: =R31*T31 -> 0
A32: 27 | B32: 113 | C32: XAMDAMOV SHOVKAT ANVAROVICH | D32: 10:01:06:01:02:5104 | E32: 3 | F32: Богистон | G32: 86 | H32: 383 | I32: 383 | J32: =I32-H32 -> 0 | K32: 167 | L32: 62.86 | M32: қарори 1988 24/07/19 | N32: =I32*P32/100 -> 191500 | O32: =K32*300 -> 50100 | P32: 50000 | Q32: =N32+O32 -> 241600 | T32: 70000 | U32: =R32*T32 -> 0
A33: 28 | B33: 114 | C33: XAMDAMOV SHUXRAT SHOVKATOVICH | D33: 10:01:06:01:02:5125 | E33: 3 | F33: Богистон | G33: 86б | H33: 600 | I33: 595 | J33: =I33-H33 -> -5 | K33: 291 | L33: 54 | M33: Олди-сотди шартномаси 1-641 16/02/15 | N33: =I33*P33/100 -> 297500 | O33: =K33*300 -> 87300 | P33: 50000 | Q33: =N33+O33 -> 384800 | T33: 70000 | U33: =R33*T33 -> 0
C34: Лот жами: | E34: =E33 -> 3 | H34: =SUM(H26:H33) -> 4313 | I34: =SUM(I26:I33) -> 4359 | J34: =SUM(J26:J33) -> 46 | K34: =SUM(K26:K33) -> 1745 | L34: =SUM(L26:L33) -> 644.27 | Q34: =SUM(Q26:Q33) -> 2703000 | R34: 47 | S34: =Q34/R34 -> 57510.638 | T34: 70000 | U34: =R34*T34 -> 3290000
T35: 70000 | U35: =R35*T35 -> 0
A36: 29 | B36: 25 | C36: BAKIYEV ALIM SABITOVICH | D36: 10:01:06:01:02:5038 | E36: 4 | F36: Богистон | G36: 41 | H36: 600 | I36: 600 | J36: =I36-H36 -> 0 | K36: 298 | L36: 83.78 | M36: Ш.Хоким карори N18 0 | N36: =I36*P36/100 -> 300000 | O36: =K36*300 -> 89400 | P36: 50000 | Q36: =N36+O36 -> 389400 | T36: 70000 | U36: =R36*T36 -> 0
A37: 30 | B37: 27 | C37: AXMEDOV SHERZOD ERGASHBAYEVICH | D37: 10:01:06:01:02:5056 | E37: 4 | F37: Богистон | G37: 64 | H37: 1290 | I37: 1290 | J37: =I37-H37 -> 0 | K37: 628 | L37: 223.55 | M37: Олди-сотди шартномаси 2-5098 06/11/07 | N37: =I37*P37/100 -> 645000 | O37: =K37*300 -> 188400 | P37: 50000 | Q37: =N37+O37 -> 833400 | T37: 70000 | U37: =R37*T37 -> 0
A38: 31 | B38: 30 | C38: MAMAJONOV XASAN IKROMOVICH | D38: 10:01:07:01:01:5472 | E38: 4 | F38: Богистон | G38: 14а | H38: 1100 | I38: 700 | J38: =I38-H38 -> -400 | K38: 83.01 | L38: 83.01 | M38: Олди-сотди шартномаси 2,02102E+14 30/11/21 | N38: =I38*P38/100 -> 350000 | O38: =K38*300 -> 24903 | P38: 50000 | Q38: =N38+O38 -> 374903 | T38: 70000 | U38: =R38*T38 -> 0
A39: 32 | B39: 31 | C39: AZIMOV JAXONGIR ZAXIDOVICH | D39: 10:01:07:01:01:5141 | E39: 4 | F39: Богистон | G39: 14 | H39: 1100 | I39: 700 | J39: =I39-H39 -> -400 | K39: 254 | L39: 31.98 | M39: Қонун бўйича ворислик ҳақида гувоҳнома 30-1706 27/12/06 | N39: =I39*P39/100 -> 350000 | O39: =K39*300 -> 76200 | P39: 50000 | Q39: =N39+O39 -> 426200 | T39: 70000 | U39: =R39*T39 -> 0
A40: 33 | B40: 33 | C40: AZIMOV SATTAR XXX | D40: 10:01:06:01:02:5014 | E40: 4 | F40: Богистон | G40: 18 | H40: 945 | I40: 945 | J40: =I40-H40 -> 0 | K40: 427 | L40: 172.53 | M40: фармойиши 255 р-р 02/06/92 | N40: =I40*P40/100 -> 472500 | O40: =K40*300 -> 128100 | P40: 50000 | Q40: =N40+O40 -> 600600 | T40: 70000 | U40: =R40*T40 -> 0
...

Sheet лот бўйича хк
A1: Лот рақами | B1: Компенсация суммаси (дастлабки ҳ-к бўйича) | C1: Лот майдони (кв.м.) | D1: Компенсиация (1 кв.м. учун) | E1: 1 сўтиҳ нархи (аукцион) | F1: Тушум (аукцион) | G1: Тушум ва компенсация фарқи
A2: 1 | B2: ='Турар Лотлар '!Q14 -> 7332800 | C2: 13600 | D2: =B2/C2 -> 539.17647 | E2: 800 | F2: =C2*E2 -> 10880000 | G2: =F2-B2 -> 3547200
A3: 2 | B3: ='Турар Лотлар '!Q24 -> 3239500 | C3: 5000 | D3: =B3/C3 -> 647.9 | E3: 600 | F3: =C3*E3 -> 3000000 | G3: =F3-B3 -> -239500
A4: 3 | B4: ='Турар Лотлар '!Q34 -> 2703000 | C4: 4700 | D4: =B4/C4 -> 575.10638 | E4: 600 | F4: =C4*E4 -> 2820000 | G4: =F4-B4 -> 117000
A5: 4 | B5: ='Турар Лотлар '!Q55 -> 9830603 | C5: 13000 | D5: =B5/C5 -> 756.20023 | E5: 600 | F5: =C5*E5 -> 7800000 | G5: =F5-B5 -> -2030603
A6: 5 | B6: ='Турар Лотлар '!Q63 -> 3306800 | C6: 3800 | D6: =B6/C6 -> 870.21053 | E6: 600 | F6: =C6*E6 -> 2280000 | G6: =F6-B6 -> -1026800
A7: 6 | B7: ='Турар Лотлар '!Q67 -> 546300 | C7: 10000 | D7: =B7/C7 -> 54.63 | E7: 600 | F7: =C7*E7 -> 6000000 | G7: =F7-B7 -> 5453700
A8: 7 | B8: ='Турар Лотлар '!Q79 -> 4161400 | C8: 4600 | D8: =B8/C8 -> 904.65217 | E8: 600 | F8: =C8*E8 -> 2760000 | G8: =F8-B8 -> -1401400
A9: 8 | B9: ='Турар Лотлар '!Q101 -> 8624700 | C9: 13000 | D9: =B9/C9 -> 663.43846 | E9: 600 | F9: =C9*E9 -> 7800000 | G9: =F9-B9 -> -824700
A10: 9 | B10: ='Турар Лотлар '!Q113 -> 13770700 | C10: 10000 | D10: =B10/C10 -> 1377.07 | E10: 600 | F10: =C10*E10 -> 6000000 | G10: =F10-B10 -> -7770700
A11: 10 | B11: ='Турар Лотлар '!Q119 -> 1593500 | C11: 2500 | D11: =B11/C11 -> 637.4 | E11: 600 | F11: =C11*E11 -> 1500000 | G11: =F11-B11 -> -93500
A12: 11 | B12: ='Турар Лотлар '!Q120 -> 0 | C12: 5000 | D12: 0 | E12: 600 | F12: =C12*E12 -> 3000000 | G12: =F12-B12 -> 3000000
A13: 12 | B13: ='Турар Лотлар '!Q127 -> 2083000 | C13: 11100 | D13: =B13/C13 -> 187.65766 | E13: 600 | F13: =C13*E13 -> 6660000 | G13: =F13-B13 -> 4577000
A14: 13 | B14: ='Турар Лотлар '!Q144 -> 8435400 | C14: 12300 | D14: =B14/C14 -> 685.80488 | E14: 600 | F14: =C14*E14 -> 7380000 | G14: =F14-B14 -> -1055400
A15: 14 | B15: ='Турар Лотлар '!Q168 -> 9098900 | C15: 8800 | D15: =B15/C15 -> 1033.9659 | E15: 600 | F15: =C15*E15 -> 5280000 | G15: =F15-B15 -> -3818900
A16: 16 | B16: ='Турар Лотлар '!Q171 -> 4285000 | C16: 6000 | D16: =B16/C16 -> 714.16667 | E16: 800 | F16: =C16*E16 -> 4800000 | G16: =F16-B16 -> 515000
A17: 17 | B17: ='Турар Лотлар '!Q175 -> 15333000 | C17: 12400 | D17: =B17/C17 -> 1236.5323 | E17: 800 | F17: =C17*E17 -> 9920000 | G17: =F17-B17 -> -5413000
A18: 18 | B18: ='Турар Лотлар '!Q179 -> 1000000 | C18: 11200 | D18: =B18/C18 -> 89.285714 | E18: 800 | F18: =C18*E18 -> 8960000 | G18: =F18-B18 -> 7960000
A19: 20 | B19: ='Турар Лотлар '!Q183 -> 1045000 | C19: 8000 | D19: =B19/C19 -> 130.625 | E19: 900 | F19: =C19*E19 -> 7200000 | G19: =F19-B19 -> 6155000
A20: 21 | B20: ='Турар Лотлар '!Q203 -> 9474150 | C20: 25000 | D20: =B20/C20 -> 378.966 | E20: 900 | F20: =C20*E20 -> 22500000 | G20: =F20-B20 -> 13025850
A21: 22 | B21: ='Турар Лотлар '!Q209 -> 8024700 | C21: 17000 | D21: =B21/C21 -> 472.04118 | E21: 900 | F21: =C21*E21 -> 15300000 | G21: =F21-B21 -> 7275300
B22: =SUM(B2:B21) -> 113888453 | C22: =SUM(C2:C21) -> 197000 | D22: =AVERAGE(D2:D21) -> 597.74148 | E22: =AVERAGE(E2:E21) -> 685 | F22: =SUM(F2:F21) -> 141840000 | G22: =F22-B22 -> 27951547
D23: ўртача

Sheet Нотурар Лотлар
A1: Учтепа тумани Катта Чўпонота махалласидаги нотурар объектлар
A2: Тартиб рақами | B2: Карта рақами | D2: Мулк эгаси | E2: Кўчаси | F2: Уй рақами | G2: Кадастр рақами | H2: Хужжати | I2: Хужжат бўйича Ер майдони, кв.м. | J2: Сотка | K2: Қурилиш ости кв.м. | L2: Захват кв.м. | M2: Снос харажатлари ($100 000)
A3: 1 | B3: 134 | C3: 14 | D3: ООО 'QODIRBEK' | E3: МКАД | G3: 10:01:06:01:02:0013 | H3: Решение хакима №261 от 12.10.2006г. Решение Хокима №1182 от 28.12.2017г. | I3: 1150 | J3: =I3/100 -> 11.5 | M3: =J3*100000 -> 1150000
A4: 2 | B4: 136 | D4: ATABAYEV ALISHER QADAMOVICH | E4: Богистон, | F4: 4а | G4: 10:01:06:01:02:0022 | H4: Договор купли-продажи №01/08 от 13.08.2020г. | I4: 211 | J4: =I4/100 -> 2.11 | M4: =J4*100000 -> 211000
A5: 3 | B5: 137 | D5: ЧП "DE LYUKS STAR" | E5: Богистон, | F5: 4а | G5: 10:01:06:01:02:0038 | H5: решение №145 от 13.03.2015г. | I5: 3663 | J5: =I5/100 -> 36.63 | M5: =J5*100000 -> 3663000
A6: 4 | B6: 138 | D6: MUXAMEDOV BEXZOD NIGMATULLAYEVICH | E6: Богистон, | F6: 4б | G6: 10:01:06:01:02:0047 | H6: Решение Хокима №78 от 12.02.2015г. | I6: 1751 | J6: =I6/100 -> 17.51 | M6: =J6*100000 -> 1751000
A7: 5 | B7: 139 | D7: ООО 'RAVSHANJON-UNIPROM ' | E7: Богистон, | F7: 4а | G7: 10:01:06:01:02:0054 | H7: Договор купли-продажи №4986 от 19.08.2014г.акт приемки в эксплуатацию завершенных строительством (реконструкцией) зданий и сооружений №28941511 от 19.03.2021г. | I7: 516 | J7: =I7/100 -> 5.16 | M7: =J7*100000 -> 516000
A8: 6 | B8: 140 | D8: ООО "RAVSHANJON-UNIPROM" | E8: Богистон, | F8: 4а | G8: 10:01:06:01:02:0029 | H8: Решение хакима №42 от 14.02.2008г. | I8: 2152 | J8: =I8/100 -> 21.52 | M8: =J8*100000 -> 2152000
A9: 7 | B9: 144 | D9: ООО "UCHTEPA AKSAZ" | E9: МКАД, | F9: 3а | G9: 10:01:06:01:02:0030 | H9: Решение хакима №1266 от 22.12.2003г. | I9: 240 | J9: =I9/100 -> 2.4 | L9: 27 | M9: =J9*100000 -> 240000
A10: 8 | B10: 155 | C10: 9 | D10: ЧП "VLAVAD RENT SERVIS" | E10: Фозилтепа, | F10: 42 | G10: 10:01:06:01:02:0040 | H10: Государственный ордер №247 от 06.09.2006г. | I10: 2328 | J10: =I10/100 -> 23.28 | M10: =J10*100000 -> 2328000
A11: 9 | B11: 157 | D11: OOO "AKSAVA" | E11: Фозилтепа, | F11: 34 | G11: 10:01:06:01:02:0008 | H11: Решение хакима №970 от 27.08.2001г. | I11: 1000 | J11: =I11/100 -> 10 | L11: 7 | M11: =J11*100000 -> 1000000
A12: 10 | B12: 158 | D12: ООО "PROF AVTO GARANT" | E12: Фозилтепа | G12: 10:01:06:01:02:0003 | H12: Решение Хокима №104 от 30.01.2017г. | I12: 333 | J12: =I12/100 -> 3.33 | M12: =J12*100000 -> 333000
A13: 11 | B13: 159 | D13: ЧП 'MTP GARANT AGROMASH SERVIS' | E13: Фозилтепа, | F13: 34 | G13: 10:01:06:01:02:0009 | H13: Государственный ордер №12 от 23.07.2015г. | I13: 4285 | J13: =I13/100 -> 42.85 | M13: =J13*100000 -> 4285000
A14: 12 | B14: 160 | D14: ООО "ERDON-SERVIS" | E14: Богистон, | F14: 4е | G14: 10:01:06:01:02:0025 | H14: Решение хакима №12 от 13.01.2009г. | I14: 3600 | J14: =I14/100 -> 36 | M14: =J14*100000 -> 3600000
A15: 13 | B15: 20 | C15: 3 | D15: ЧП "GULSHAN JILOSI" | E15: Фозилтепа | F15: 178 | G15: 10:01:06:01:02:0019 | H15: Олди сотди шартномаси 07.08.2012 й № 2/2833, Фуқаролик ишлари бўйича Тошкент шахар судининг қарори 17.03.2015 й № 10-1520/3172 | I15: 639 | J15: =I15/100 -> 6.39 | K15: 678 | M15: =J15*100000 -> 639000
A16: 14 | B16: 22 | C16: 3 | D16: MIRSOATOV UBAYDULLO ABDULLO O‘G‘LI | E16: Фозилтепа | F16: 178 | G16: 10:01:06:01:02:0031 | H16: Олди сотди шартномаси 06.03.2019 й № 201900061001688. | J16: =I16/100 -> 0 | K16: 67 | M16: =K16*1000 -> 67000
A17: 15 | B17: 23 | D17: SIDIKOV BAXODIR AKMALOVICH | E17: Фозилтепа | F17: 178 | G17: 10:01:06:01:02:0032 | H17: Олди сотди шартномаси 03.06.2021 й № 202102108003387. | I17: 1045 | J17: =I17/100 -> 10.45 | K17: 892 | M17: =J17*100000 -> 1045000
A18: 16 | B18: 2 | D18: ГП "Спецавтообъединение Главного управления здравоохранения г.Ташкента" | E18: Фозилтепа, | F18: 34 | G18: 10:01:06:01:02:0005 | H18: Приказ №65 от 16.02.1995г. Приказ №289 от 13.10.2017г. | I18: 42507 | J18: =I18/100 -> 425.07 | M18: 8000000
A19: 17 | B19: 1 | D19: ООО "TOSHKENT SHAHAR SUV TA`MINOTI" | E19: Фозилтепа, | F19: 30 | G19: 10:01:06:01:02:0021 | H19: Учтепа туман хокимининг карори 10.03.2017 й. № 238 | I19: 14394 | J19: =I19/100 -> 143.94 | M19: 7000000
D20: Жами: | I20: =SUM(I3:I29) -> 24573 | J20: =SUM(J3:J29) -> 245.73 | L20: =SUM(L3:L29) -> 117 | M20: =SUM(M3:M19) -> 37980000
A22: Компенсация берилмайдиган ҳамада бузилмайдиган нотурар объектлар
A23: Тартиб рақами | B23: Карта рақами | D23: Мулк эгаси | E23: Кўчаси | F23: Уй рақами | G23: Кадастр рақами | H23: Хужжати | I23: Хужжат бўйича Ер майдони, кв.м. | J23: Сотка | L23: Захват кв.м. | M23: Снос харажатлари ($100 000)
A24: 18 | B24: 21 | D24: "DRENAJLAR VA KOLLEKTORLARNI TA'MIRLASH VA SAQLASH IXTISOSLASHTIRILGAN BOSHKARMASI"DAVLAT MUASSASAS | E24: Фозилтепа | F24: 178 | G24: 10:01:06:01:02:0049 | H24: Мехнаткашлар депутатлариТошкент шахар советининг ижроия комитетининг қарори 01.07.1969 й № 192, Тошкент шахар совет халқ депутатлари комитетининг қарори 06.03.1987 й № 155/5, Акмал Икромов туман хокимининг қарори 29.10.1999 й № 1493. | I24: 1013 | J24: =I24/100 -> 10.13
A25: 19 | B25: 24 | D25: XUKUMAT OB'EKLARIDA XIZMAT KO'RSATISH BO'YICHA MAXSUS BOSHQARMA | E25: Фозилтепа | F25: 178 | G25: 10:01:06:01:02:0014 | H25: Ўзбекистон Республикаси Вазирлар Махкамасининг фармойиши 20.03.2003 й № 166-ф | I25: 19805 | J25: =I25/100 -> 198.05
A26: 20 | B26: 135 | D26: Сход граждан махалли 'CHO'PON OTA' | E26: Богистон, | F26: 5 | G26: 10:01:06:01:02:0052 | H26: Договор аренды земельного участка №1-14-1-0283-12 от 26.08.2012г. | I26: 1011 | J26: =I26/100 -> 10.11
A27: 21 | B27: 156 | D27: ГУП "SUVSOZ" | E27: Фозилтепа, | F27: 42 | G27: 10:01:06:01:02:0039 | H27: Решение №708/33 от 04.12.1987г. Государственный ордер подтверждающий права собственности №16 от 05.05.2020г. | I27: 5308 | J27: =I27/100 -> 53.08
A29: 1 | B29: 28 | D29: G‘AFURJONOV SHAHZOD ALISHER O‘G‘LI | E29: Фозилтепа | G29: 10:01:06:01:02:0017 | H29: Олди сотди шартномаси 05.02.2021 й № 202101915001388. | I29: 1660 | J29: =I29/100 -> 16.6 | K29: 52 | L29: 83
A30: 2 | B30: 7 | D30: XAMIDOVA PARIDA KABILOVNA | E30: Богобод | F30: 269,271а,273 | G30: 10:01:06:01:02:0055 | H30: Учтепа туман хокимининг қарори 27.05.2016 й № 398 | I30: 4144 | J30: =I30/100 -> 41.44 | K30: 1791
A31: 3 | B31: 25 | D31: ООО "TURON MEROS" | E31: Фозилтепа | F31: 178 | G31: 10:01:06:01:02:0058 | H31: Тошкент шахар хокими 01.06.2021 й № 650 | I31: 15000 | J31: =I31/100 -> 150
A32: 4 | B32: 27 | D32: ООО "SOFIYA QANDOLAT" | E32: Фозилтепа | G32: 10:01:06:01:02:0057 | H32: Тошкент шахар хокими 07.04.2021 й № 386 | I32: 8000 | J32: =I32/100 -> 80 | K32: 7628
A33: 5 | B33: 29 | D33: ООО "MADINA-MUXLISA STAR" (Парк) | E33: Фозилтепа, | F33: 251 | G33: 10:01:06:01:02:0016 | H33: Учтепа туман хокими қарори 14.12.2017 й № 1140 | I33: 45200 | J33: =I33/100 -> 452
A34: 23 | D34: Жами: | I34: =SUM(I19:I27) -> 41531 | J34: =SUM(J19:J27) -> 415.31 | L34: =SUM(L19:L27) -> 0

Sheet Турар Вьетнам карта
A1: Учтепа тумани Катта Чўпонота махалласидаги турар уй жойлар
A2: № | B2: К/р | D2: Мулкдор | E2: Кадастр рақами | F2: Кўча | G2: Уй рақами | H2: Хужжат бўйича Ер майдони, кв.м. | I2: Умумий ер майдони кв.м. | J2: Ўзбошимча ер майдони кв.м. | K2: Қурилиш оости майдони кв.м. | L2: Яшаш майдони кв.м. | M2: Хуқуқ тури | N2: Ер нархи кв.м. $ 500-800 | O2: Бино нархи $ 300
A4: 1 | B4: 1 | C4: 1 | D4: MERNIY ANATOLIY GRIGOREVICH | E4: 10:01:06:01:02:5074 | F4: Богистон | G4: 257 | H4: 2500 | I4: 2500 | J4: =I4-H4 -> 0 | K4: 135 | L4: 31.84 | M4: Ҳадя шартномаси 20-331 08/05/03 | N4: =I4*P4/100 -> 1750000 | O4: =K4*300 -> 40500 | P4: 70000 | Q4: =N4+O4 -> 1790500
A5: 2 | B5: 2 | C5: 1 | D5: NASIROVA FOTIMA XAMIDULLAYEVNA | E5: 10:01:06:01:02:5136 | F5: Х Турсункулов | G5: 259 | H5: 2400 | I5: 3200 | J5: =I5-H5 -> 800 | K5: 675 | L5: 115.49 | M5: Олди-сотди шартномаси 927 27/02/03 | N5: =I5*P5/100 -> 2240000 | O5: =K5*300 -> 202500 | P5: 70000 | Q5: =N5+O5 -> 2442500
A6: 3 | B6: 4 | C6: 1 | D6: TULAGANOV AXMADJON TAGIROVICH | E6: 10:01:06:01:02:5075 | F6: Богистон | G6: 261 | H6: 1390 | I6: 1390 | J6: =I6-H6 -> 0 | K6: 588 | L6: 231.64 | M6: Олди-сотди шартномаси 2,02102E+14 27/12/21 | N6: =I6*P6/100 -> 973000 | O6: =K6*300 -> 176400 | P6: 70000 | Q6: =N6+O6 -> 1149400
A7: 4 | B7: 5 | C7: 1 | D7: YAFUNYAYEV MURAD FARIDOVICH | E7: 10:01:06:01:02:5076 | F7: Богистон | G7: 263 | H7: 4900 | I7: 5098 | J7: =I7-H7 -> 198 | K7: 311 | L7: 257.26 | M7: Олди-сотди шартномаси 12-901 14/10/99 | N7: =I7*P7/100 -> 2549000 | O7: =K7*300 -> 93300 | P7: 50000 | Q7: =N7+O7 -> 2642300
H8: =SUM(H4:H7) -> 11190 | I8: =SUM(I4:I7) -> 12188 | J8: =SUM(J4:J7) -> 998 | K8: =SUM(K4:K7) -> 1709 | L8: =SUM(L4:L7) -> 636.23 | M8: =SUM(M4:M7) -> 0 | N8: =SUM(N4:N7) -> 7512000 | O8: =SUM(O4:O7) -> 512700 | ... Q8: =SUM(Q4:Q7) -> 8024700
A9: 5 | B9: 8 | C9: 2 | D9: XUSNITDINOV TAXIRDJAN XUDAYBERGENOVICH | E9: 10:01:06:01:02:5123 | F9: Богистон | G9: 275 | H9: 636 | I9: 636 | J9: =I9-H9 -> 0 | K9: 413 | L9: 105.19 | M9: Қонун бўйича ворислик ҳақида гувоҳнома 2-6149 04/12/90 | N9: =I9*P9/100 -> 318000 | O9: =K9*300 -> 123900 | P9: 50000 | Q9: =N9+O9 -> 441900
A10: 6 | B10: 9 | C10: 2 | D10: XUSNITDINOV DILSHOD TAXIRJANOVICH | E10: 10:01:06:01:02:5123/01 | F10: Богистон | G10: 275б | H10: 398 | I10: 398 | J10: =I10-H10 -> 0 | K10: 134 | L10: 66.01 | M10: Ҳадя шартномаси 2,019E+14 02/07/19 | N10: =I10*P10/100 -> 199000 | O10: =K10*300 -> 40200 | P10: 50000 | Q10: =N10+O10 -> 239200
A11: 7 | B11: 10 | C11: 2 | D11: ACHILOVA GULBAXOR RIXSIYEVNA | E11: 10:01:06:01:02:5078/01 | F11: Богистон | G11: 275г | H11: 300 | I11: 300 | J11: =I11-H11 -> 0 | K11: 117 | L11: 52.72 | M11: Ҳадя шартномаси 2,01901E+14 15/02/19 | N11: =I11*P11/100 -> 150000 | O11: =K11*300 -> 35100 | P11: 50000 | Q11: =N11+O11 -> 185100
A12: 8 | B12: 11 | C12: 2 | D12: XAITMUXAMEDOVA DILORAM TOXIRJONOVNA | E12: 10:01:06:01:02:5154 | F12: Богистон | G12: 275в | H12: 391 | I12: 391 | J12: =I12-H12 -> 0 | K12: 233 | L12: 89.46 | M12: Ҳадя шартномаси 2,02002E+14 13/11/20 | N12: =I12*P12/100 -> 195500 | O12: =K12*300 -> 69900 | P12: 50000 | Q12: =N12+O12 -> 265400
A13: 9 | B13: 12 | C13: 2 | D13: KARIMOVA MALIKA TAXIRDJANOVNA | E13: 10:01:06:01:02:5078 | F13: Богистон | G13: 275а | H13: 845 | I13: 845 | J13: =I13-H13 -> 0 | K13: 276 | L13: 80.59 | M13: Ҳадя шартномаси 2,01901E+14 15/02/19 | N13: =I13*P13/100 -> 422500 | O13: =K13*300 -> 82800 | P13: 50000 | Q13: =N13+O13 -> 505300
A14: 10 | B14: 13 | C14: 2 | D14: XUDJAMURATOV ALISHER AVLAYEVICH | E14: 10:01:06:01:02:5156 | F14: Богистон | G14: 275д | H14: 600 | I14: 659 | J14: =I14-H14 -> 59 | K14: 22 | L14: 16.24 | M14: Олди-сотди шартномаси 2,02002E+14 16/09/20 | N14: =I14*P14/100 -> 329500 | O14: =K14*300 -> 6600 | P14: 50000 | Q14: =N14+O14 -> 336100
A15: 11 | B15: 14 | C15: 2 | D15: XASHIMOV XABIBULLA XASANOVICH | E15: 10:01:06:01:02:5079 | F15: Богистон | G15: 277 | H15: 754 | I15: 779 | J15: =I15-H15 -> 25 | K15: 470 | L15: 217.57 | M15: Ҳадя шартномаси Р-р1-2975 09.10.2003 | N15: =I15*P15/100 -> 623200 | O15: =K15*300 -> 141000 | P15: 80000 | Q15: =N15+O15 -> 764200
A16: 12 | B16: 15 | C16: 2 | D16: XASHIMOV ABDURAXMON ABDUKASIMOVICH | E16: 10:01:06:01:02:5144 | F16: Богистон | G16: 279а | H16: 535 | I16: 535 | J16: =I16-H16 -> 0 | K16: 222 | L16: 85.84 | M16: Ҳадя шартномаси 1-3869 13/10/16 | N16: =I16*P16/100 -> 428000 | O16: =K16*300 -> 66600 | P16: 80000 | Q16: =N16+O16 -> 494600
A17: 13 | B17: 16 | C17: 2 | D17: XASHIMOV MURAT XUSANOVICH | E17: 10:01:06:01:02:5141 | F17: Богистон | G17: 281 | H17: 1093 | I17: 1093 | J17: =I17-H17 -> 0 | K17: 460 | L17: 182.68 | M17: Қонун бўйича ворислик ҳақида гувоҳнома 2,019E+14 16/09/19 | N17: =I17*P17/100 -> 546500 | O17: =K17*300 -> 138000 | P17: 50000 | Q17: =N17+O17 -> 684500
A18: 14 | B18: 17 | C18: 2 | D18: AXRAROV SANJAR YAXYAYEVICH | E18: 10:01:06:01:02:5080 | F18: Богистон | G18: 279 | H18: 1265 | I18: 2509 | J18: =I18-H18 -> 1244 | K18: 653 | L18: 68.49 | M18: Келишув битими 2,019E+14 06/08/19 | N18: =I18*P18/100 -> 1630850 | O18: =K18*300 -> 195900 | P18: 65000 | Q18: =N18+O18 -> 1826750
A19: 15 | B19: 18 | C19: 2 | D19: XALILOV ABDUSAMAT ABDUJALILOVICH | E19: 10:01:06:01:02:5132 | F19: Богистон | G19: 283а | H19: 600 | I19: 600 | J19: =I19-H19 -> 0 | K19: 167 | L19: 30.53 | M19: Васиятнома бўйича меросга бўлган ҳуқуқ ҳақидаги гувоҳномаси 1-441 16/02/17 | N19: =I19*P19/100 -> 480000 | O19: =K19*300 -> 50100 | P19: 80000 | Q19: =N19+O19 -> 530100
A20: 16 | B20: 19 | C20: 2 | D20: XALILOV ABDUSATTOR ABDUJALILOVICH | E20: 10:01:06:01:02:5081 | F20: Богистон | G20: 283 | H20: 2114 | I20: 2114 | J20: =I20-H20 -> 0 | K20: 556 | L20: 233.3 | M20: Қонун бўйича ворислик ҳақида гувоҳнома 1-439 16/02/17 | N20: =I20*P20/100 -> 1057000 | O20: =K20*300 -> 166800 | P20: 50000 | Q20: =N20+O20 -> 1223800
A21: 17 | B21: 26 | C21: 2 | D21: BIRYUKOVA ROZA GLIMYANOVNA | E21: 10:01:06:01:02:5135 | F21: Фозилтепа | G21: 244 | H21: 1010 | I21: 1010 | J21: =I21-H21 -> 0 | K21: 228 | L21: 76.5 | M21: қарори 227 28/03/18 | N21: =I21*P21/100 -> 505000 | O21: =K21*300 -> 68400 | P21: 50000 | Q21: =N21+O21 -> 573400
H22: =SUM(H9:H21) -> 10541 | I22: =SUM(I9:I21) -> 11869 | J22: =SUM(J9:J21) -> 1328 | K22: =SUM(K9:K21) -> 3951 | L22: =SUM(L9:L21) -> 1305.12 | M22: =SUM(M9:M21) -> 0 | N22: =SUM(N9:N21) -> 6885050 | O22: =SUM(O9:O21) -> 1185300 | ... Q22: =SUM(Q9:Q21) -> 8070350
A23: 18 | C23: 3 | D23: ASAMOVA NOZIMA AKMALOVNA | E23: 10:01:06:01:02:5073 | F23: Боғобод | G23: 180 | H23: 1020 | I23: 1020 | K23: 390 | N23: =I23*P23/100 -> 510000 | O23: =K23*300 -> 117000 | P23: 50000 | Q23: =N23+O23 -> 627000
A24: 19 | C24: 3 | D24: ASAMOVA NAILYA NASIROVNA | E24: 10:01:06:01:02:5161 | F24: Боғобод | G24: 180а | K24: 236 | N24: =I24*P24/100 -> 0 | O24: =K24*300 -> 70800 | P24: 50000 | Q24: =N24+O24 -> 70800
H25: =SUM(H23:H24) -> 1020 | I25: =SUM(I23:I24) -> 1020 | J25: =SUM(J23:J24) -> 0 | K25: =SUM(K23:K24) -> 626 | L25: =SUM(L23:L24) -> 0 | M25: =SUM(M23:M24) -> 0 | N25: =SUM(N23:N24) -> 510000 | O25: =SUM(O23:O24) -> 187800 | ... Q25: =SUM(Q23:Q24) -> 697800
A26: 20 | B26: 68 | C26: 8 | D26: XAMIDOV KOZIM DJURAYEVICH | E26: 10:01:06:01:02:5115 | F26: Богистон, туп 5 | G26: 97 | H26: 734 | I26: 734 | J26: =I26-H26 -> 0 | K26: 378 | L26: 121.55 | M26: Ҳадя шартномаси 1-4258 03/12/15 | N26: =I26*P26/100 -> 367000 | O26: =K26*300 -> 113400 | P26: 50000 | Q26: =N26+O26 -> 480400
A27: 21 | B27: 69 | C27: 8 | D27: MUMINOV SAGDULLA MOVLANOVICH | E27: 10:01:06:01:02:5036 | F27: ул. Богистон, дом | G27: 121 | H27: 520 | I27: 520 | J27: =I27-H27 -> 0 | K27: 305 | L27: 132.96 | M27: туман ижроия қўмитаси қарори 11-3/2 23/01/92 | N27: =I27*P27/100 -> 260000 | O27: =K27*300 -> 91500 | P27: 50000 | Q27: =N27+O27 -> 351500
A28: 22 | B28: 70 | C28: 8 | D28: MIRXADIYEV SHERZOD MIRAXMADOVICH | E28: 10:01:06:01:02:5037/01 | F28: ул. Богистон, дом | G28: 40а | H28: 380 | I28: 380 | J28: =I28-H28 -> 0 | K28: 240 | L28: 110.6 | M28: Олди-сотди шартномаси 7253 11/12/07 | N28: =I28*P28/100 -> 190000 | O28: =K28*300 -> 72000 | P28: 50000 | Q28: =N28+O28 -> 262000
A29: 23 | B29: 71 | C29: 8 | D29: YAKUBDJANOVA MOXIRA MELSOVNA | E29: 10:01:06:01:02:5037 | F29: ул. Богистон, дом | G29: 40 | H29: 500 | I29: 500 | J29: =I29-H29 -> 0 | K29: 333 | L29: 255.79 | M29: Олди-сотди шартномаси 15-576 11/06/10 | N29: =I29*P29/100 -> 250000 | O29: =K29*300 -> 99900 | P29: 50000 | Q29: =N29+O29 -> 349900
A30: 24 | B30: 73 | C30: 8 | D30: XODIYEV RAXMAT MAXKAMOVICH | E30: 10:01:06:01:02:5120 | F30: Богистон | G30: 63 | H30: 286 | I30: 286 | J30: =I30-H30 -> 0 | K30: 141 | L30: 93.53 | M30: қарори 612 05/10/18 | N30: =I30*P30/100 -> 143000 | O30: =K30*300 -> 42300 | P30: 50000 | Q30: =N30+O30 -> 185300
H31: =SUM(H26:H30) -> 2420 | I31: =SUM(I26:I30) -> 2420 | J31: =SUM(J26:J30) -> 0 | K31: =SUM(K26:K30) -> 1397 | L31: =SUM(L26:L30) -> 714.43 | M31: =SUM(M26:M30) -> 0 | N31: =SUM(N26:N30) -> 1210000 | O31: =SUM(O26:O30) -> 419100 | ... Q31: =SUM(Q26:Q30) -> 1629100
A32: 25 | B32: 5 | C32: 9 | D32: SHERXANOV SHAHZOD RAVSHAN O‘G‘LI | E32: 10:01:06:01:02:5052 | F32: Богистон | G32: 67 | H32: 600 | I32: 600 | J32: =I32-H32 -> 0 | K32: 407 | L32: 201.6 | M32: Олди-сотди шартномаси 2,019E+14 27/12/19 | N32: =I32*P32/100 -> 300000 | O32: =K32*300 -> 122100 | P32: 50000 | Q32: =N32+O32 -> 422100
A33: 26 | B33: 74 | C33: 9 | D33: YAKUBOV SAMUK NABIYEVICH | E33: 10:01:06:01:02:5028 | F33: Богистон | G33: 107 | H33: 660 | I33: 660 | J33: =I33-H33 -> 0 | K33: 404 | L33: 110.21 | M33: Қонун бўйича ворислик ҳақида гувоҳнома 8-532 30/01/06 | N33: =I33*P33/100 -> 330000 | O33: =K33*300 -> 121200 | P33: 50000 | Q33: =N33+O33 -> 451200
A34: 27 | B34: 75 | C34: 9 | D34: YAKUBOV SAMUK NABIYEVICH | E34: 10:01:06:01:02:5101 | F34: Богистон | G34: 105 | H34: 1592 | I34: 663 | J34: =I34-H34 -> -929 | K34: 146 | L34: 72.12 | M34: қарори 314/26 26/12/91 | N34: =I34*P34/100 -> 331500 | O34: =K34*300 -> 43800 | P34: 50000 | Q34: =N34+O34 -> 375300
A35: 28 | B35: 76 | C35: 9 | D35: YAKUBOV SHOKIRJON SAMUKOVICH | E35: 10:01:06:01:02:5101/01 | F35: Богистон | G35: 105а | H35: 1592 | I35: 929 | J35: =I35-H35 -> -663 | K35: 465 | L35: 224.02 | M35: Ҳадя шартномаси 2,019E+14 21/01/19 | N35: =I35*P35/100 -> 464500 | O35: =K35*300 -> 139500 | P35: 50000 | Q35: =N35+O35 -> 604000
A36: 29 | B36: 77 | C36: 9 | D36: BABAJANOV BEHZOD POLVANNAZIROVICH | E36: 10:01:06:01:02:5003 | F36: Богистон | G36: 103 | H36: 488 | I36: 488 | J36: =I36-H36 -> 0 | K36: 93 | L36: 39.4 | M36: Олди-сотди шартномаси 2,02102E+14 16/12/21 | N36: =I36*P36/100 -> 244000 | O36: =K36*300 -> 27900 | P36: 50000 | Q36: =N36+O36 -> 271900
A37: 30 | B37: 78 | C37: 9 | D37: YAKUBDJANOVA OZODAGUL DJARKINOVNA | E37: 10:01:06:01:02:5001 | F37: Богистон | G37: 101 | H37: 600 | I37: 670 | J37: =I37-H37 -> 70 | K37: 134 | L37: 43.11 | M37: Олди-сотди шартномаси 4710 07/09/18 | N37: =I37*P37/100 -> 335000 | O37: =K37*300 -> 40200 | P37: 50000 | Q37: =N37+O37 -> 375200
A38: 31 | B38: 79 | C38: 9 | D38: BAKAYEVA XODJINISA NABIYEVNA | E38: 10:01:06:01:02:5002 | F38: Богистон | G38: 1 | H38: 558 | I38: 572 | J38: =I38-H38 -> 14 | K38: 295 | L38: 99.59 | M38: Курилиш шартномаси 1336р9-232 19/02/92 | N38: =I38*P38/100 -> 343200 | O38: =K38*300 -> 88500 | P38: 60000 | Q38: =N38+O38 -> 431700
A39: 32 | B39: 80 | C39: 9 | D39: ACHILOV ABDURASHID RIXSIVAYEVICH | E39: 10:01:06:01:02:5095 | F39: Богистон | G39: 3 | H39: 1310 | I39: 1310 | J39: =I39-H39 -> 0 | K39: 639 | L39: 269.67 | M39: Васиятнома бўйича ворислик ҳақида гувоҳномаси 1-1714 30/04/12 | N39: =I39*P39/100 -> 786000 | O39: =K39*300 -> 191700 | P39: 60000 | Q39: =N39+O39 -> 977700
A40: 33 | B40: 81 | C40: 9 | D40: Ачилов Абдурахман | E40: 10:01:06:01:02:5138 | F40: Богистон | G40: 38 (34) | H40: 885 | I40: 904 | J40: =I40-H40 -> 19 | K40: 508 | L40: 125.99 | M40: а карори.277-1-23.14 | N40: =I40*P40/100 -> 452000 | O40: =K40*300 -> 152400 | P40: 50000 | Q40: =N40+O40 -> 604400
A41: 34 | B41: 82 | C41: 9 | D41: KADIROV RUSTAM SULTANOVICH | E41: 10:01:06:01:02:5160 | F41: Богистон | G41: 7а | H41: 430 | I41: 430 | J41: =I41-H41 -> 0 | K41: 179 | L41: 28.6 | M41: Олди-сотди шартномаси 2,02102E+14 15/10/21 | N41: =I41*P41/100 -> 215000 | O41: =K41*300 -> 53700 | P41: 50000 | Q41: =N41+O41 -> 268700
...

Sheet Нотурар Лотлар Вьет
A1: Учтепа тумани Катта Чўпонота махалласидаги нотурар объектлар
A2: Тартиб рақами | B2: Карта рақами | D2: Мулк эгаси | E2: Кўчаси | F2: Уй рақами | G2: Кадастр рақами | H2: Хужжати | I2: Хужжат бўйича Ер майдони, кв.м. | J2: Сотка | K2: Қурилиш ости кв.м. | L2: Захват кв.м. | M2: Снос харажатлари ($100 000)
A4: 13 | B4: 20 | C4: 3 | D4: ЧП "GULSHAN JILOSI" | E4: Фозилтепа | F4: 178 | G4: 10:01:06:01:02:0019 | H4: Олди сотди шартномаси 07.08.2012 й № 2/2833, Фуқаролик ишлари бўйича Тошкент шахар судининг қарори 17.03.2015 й № 10-1520/3172 | I4: 639 | J4: =I4/100 -> 6.39 | K4: 678 | M4: =J4*100000 -> 639000
A5: 14 | B5: 22 | C5: 3 | D5: MIRSOATOV UBAYDULLO ABDULLO O‘G‘LI | E5: Фозилтепа | F5: 178 | G5: 10:01:06:01:02:0031 | H5: Олди сотди шартномаси 06.03.2019 й № 201900061001688. | J5: =I5/100 -> 0 | K5: 67 | M5: =K5*1000 -> 67000
I6: =SUM(I4:I5) -> 639 | J6: =SUM(J4:J5) -> 6.39 | K6: =SUM(K4:K5) -> 745 | L6: =SUM(L4:L5) -> 0 | M6: =SUM(M4:M5) -> 706000
A7: 15 | B7: 23 | C7: 4 | D7: SIDIKOV BAXODIR AKMALOVICH | E7: Фозилтепа | F7: 178 | G7: 10:01:06:01:02:0032 | H7: Олди сотди шартномаси 03.06.2021 й № 202102108003387. | I7: 1045 | J7: =I7/100 -> 10.45 | K7: 892 | M7: =J7*100000 -> 1045000
I8: =SUM(I7) -> 1045 | J8: =SUM(J7) -> 10.45 | K8: =SUM(K7) -> 892 | L8: =SUM(L7) -> 0 | M8: =SUM(M7) -> 1045000
A9: 9 | B9: 157 | C9: 5 | D9: OOO "AKSAVA" | E9: Фозилтепа, | F9: 34 | G9: 10:01:06:01:02:0008 | H9: Решение хакима №970 от 27.08.2001г. | I9: 1000 | J9: =I9/100 -> 10 | L9: 7 | M9: =J9*100000 -> 1000000
A10: 10 | B10: 158 | C10: 5 | D10: ООО "PROF AVTO GARANT" | E10: Фозилтепа | G10: 10:01:06:01:02:0003 | H10: Решение Хокима №104 от 30.01.2017г. | I10: 333 | J10: =I10/100 -> 3.33 | M10: =J10*100000 -> 333000
A11: 11 | B11: 159 | C11: 5 | D11: ЧП 'MTP GARANT AGROMASH SERVIS' | E11: Фозилтепа, | F11: 34 | G11: 10:01:06:01:02:0009 | H11: Государственный ордер №12 от 23.07.2015г. | I11: 4285 | J11: =I11/100 -> 42.85 | M11: =J11*100000 -> 4285000
A12: 18 | B12: 2 | C12: 5 | D12: ГП "Спецавтообъединение Главного управления здравоохранения г.Ташкента" | E12: Фозилтепа, | F12: 34 | G12: 10:01:06:01:02:0005 | H12: Приказ №65 от 16.02.1995г. Приказ №289 от 13.10.2017г. | I12: 42507 | J12: =I12/100 -> 425.07 | M12: 8000000
A13: 19 | B13: 1 | C13: 5 | D13: ООО "TOSHKENT SHAHAR SUV TA`MINOTI" | E13: Фозилтепа, | F13: 30 | G13: 10:01:06:01:02:0021 | H13: Учтепа туман хокимининг карори 10.03.2017 й. № 238 | I13: 14394 | J13: =I13/100 -> 143.94 | M13: 7000000
I14: =SUM(I9:I13) -> 62519 | J14: =SUM(J9:J13) -> 625.19 | K14: =SUM(K9:K13) -> 0 | L14: =SUM(L9:L13) -> 7 | M14: =SUM(M9:M13) -> 20618000
A15: 16 | C15: 8 | D15: G‘OFUROV SA’DULLA TAXIR O‘G‘LI | E15: Богистон кўчаси | F15: 99а | I15: 436 | J15: =I15/100 -> 4.36 | K15: 175 | M15: =J15*100000 -> 436000
A16: 17 | C16: 8 | D16: OOO "RESTAVRATOR UNIVERSAL" | E16: Богистон кўчаси | F16: 99Б | I16: 662 | J16: =I16/100 -> 6.62 | K16: 217 | M16: =J16*100000 -> 662000
I17: =SUM(I15:I16) -> 1098 | J17: =SUM(J15:J16) -> 10.98 | K17: =SUM(K15:K16) -> 392 | L17: =SUM(L15:L16) -> 0 | M17: =SUM(M15:M16) -> 1098000
A18: 8 | B18: 155 | C18: 9 | D18: ЧП "VLAVAD RENT SERVIS" | E18: Фозилтепа, | F18: 42 | G18: 10:01:06:01:02:0040 | H18: Государственный ордер №247 от 06.09.2006г. | I18: 2328 | J18: =I18/100 -> 23.28 | M18: =J18*100000 -> 2328000
I19: =SUM(I18) -> 2328 | J19: =SUM(J18) -> 23.28 | K19: =SUM(K18) -> 0 | L19: =SUM(L18) -> 0 | M19: =SUM(M18) -> 2328000
A20: 2 | B20: 136 | C20: 12 | D20: ATABAYEV ALISHER QADAMOVICH | E20: Богистон, | F20: 4а | G20: 10:01:06:01:02:0022 | H20: Договор купли-продажи №01/08 от 13.08.2020г. | I20: 211 | J20: =I20/100 -> 2.11 | M20: =J20*100000 -> 211000
A21: 3 | B21: 137 | C21: 12 | D21: ЧП "DE LYUKS STAR" | E21: Богистон, | F21: 4а | G21: 10:01:06:01:02:0038 | H21: решение №145 от 13.03.2015г. | I21: 3663 | J21: =I21/100 -> 36.63 | M21: =J21*100000 -> 3663000
A22: 4 | B22: 138 | C22: 12 | D22: MUXAMEDOV BEXZOD NIGMATULLAYEVICH | E22: Богистон, | F22: 4б | G22: 10:01:06:01:02:0047 | H22: Решение Хокима №78 от 12.02.2015г. | I22: 1751 | J22: =I22/100 -> 17.51 | M22: =J22*100000 -> 1751000
A23: 5 | B23: 139 | C23: 12 | D23: ООО 'RAVSHANJON-UNIPROM ' | E23: Богистон, | F23: 4а | G23: 10:01:06:01:02:0054 | H23: Договор купли-продажи №4986 от 19.08.2014г.акт приемки в эксплуатацию завершенных строительством (реконструкцией) зданий и сооружений №28941511 от 19.03.2021г. | I23: 516 | J23: =I23/100 -> 5.16 | M23: =J23*100000 -> 516000
A24: 6 | B24: 140 | C24: 12 | D24: ООО "RAVSHANJON-UNIPROM" | E24: Богистон, | F24: 4а | G24: 10:01:06:01:02:0029 | H24: Решение хакима №42 от 14.02.2008г. | I24: 2152 | J24: =I24/100 -> 21.52 | M24: =J24*100000 -> 2152000
A25: 12 | B25: 160 | C25: 12 | D25: ООО "ERDON-SERVIS" | E25: Богистон, | F25: 4е | G25: 10:01:06:01:02:0025 | H25: Решение хакима №12 от 13.01.2009г. | I25: 3600 | J25: =I25/100 -> 36 | M25: =J25*100000 -> 3600000
I26: =SUM(I20:I25) -> 11893 | J26: =SUM(J20:J25) -> 118.93 | K26: =SUM(K20:K25) -> 0 | L26: =SUM(L20:L25) -> 0 | M26: =SUM(M20:M25) -> 11893000
A27: 1 | B27: 134 | C27: 14 | D27: ООО 'QODIRBEK' | E27: МКАД | G27: 10:01:06:01:02:0013 | H27: Решение хакима №261 от 12.10.2006г. Решение Хокима №1182 от 28.12.2017г. | I27: 1150 | J27: =I27/100 -> 11.5 | M27: =J27*100000 -> 1150000
I28: =SUM(I27) -> 1150 | J28: =SUM(J27) -> 11.5 | K28: =SUM(K27) -> 0 | L28: =SUM(L27) -> 0 | M28: =SUM(M27) -> 1150000
